Workbook
Name AHV_1: #REF!
Name AHV_2: #REF!
Name AHV_3: #REF!
Name AHV_4: #REF!
Name AHV_5: #REF!
Name AHV_6: #REF!
Name AlterMann: #REF!
Name asdf: #REF!
Name D: #REF!
Name Dossier_End2End_1: #REF!
Name DossierName: #REF!
Name DossierName1: #REF!
Name First_Feamale_1: #REF!
Name First_Feamale_3: #REF!
Name First_Female_2: #REF!
Name First_Female_3: #REF!
Name First_Female_4: #REF!
Name First_Female_5: #REF!
Name FrauAlter: #REF!
Name Kind1Alter: #REF!
Name Kind2Alter: #REF!
Name KlientName: #REF!
Name NameMutter: #REF!
Name NameSohn: #REF!
Name NameTochter: #REF!
Name NameVater: #REF!
Name RandomStart: #REF!
Name s: #REF!
Name SpeedFaktor: '000'!$B$27
Name URL: #REF!
Name URLAVENTIS: #REF!
Name URLDemoAventis: #REF!
Name URLDevAventis: #REF!
Name URLTestAventis: #REF!
Name URLTestrun: #REF!

Sheet 000
A1: StepNumber | B1: Action | C1: TestData | D1: Screenshot | F1: video | G1: =30*1000*SpeedFaktor -> 30000 | H1: 10 | S1: Testresult | T1: 09.12.2024 10:35:06 | U1: 09.12.2024 11:14:33 | V1: Hoch | X1: 22.07.2025 05:11:20 | Y1: Message | Z1: 22.07.2025 09:53:01 | AA1: Message | AB1: 22.07.2025 15:36:51 | AC1: Message | AD1: 22.07.2025 18:44:05 | AE1: Message | AF1: 22.07.2025 19:54:04 | AG1: Message | AH1: 04.02.2025 13:50:39 | AI1: Hoch | AJ1: 28.03.2025 10:25:49 | AK1: Hoch | AL1: 31.03.2025 18:57:12 | AM1: Hoch | AN1: 01.04.2025 00:27:19 | AO1: Hoch | AP1: 01.04.2025 23:50:20 | AQ1: Hoch | AR1: 09.04.2025 | AS1: Hoch | AT1: 09.04.2025 20:54:34 | AU1: Hoch | AV1: 25.06.2025 16:52:40 | AW1: Hoch | AX1: 25.06.2025 19:45:42 | AY1: Hoch | AZ1: 26.06.2025 08:23:51 | BA1: Message 26.06.2025 08:23:51 | BB1: 05.07.2025 02:04:53 | BC1: Message 05.07.2025 02:04:53 | BD1: 22.07.2025 22:30:01 | BE1: Message | BF1: 23.07.2025 08:43:42 | BG1: Message | BH1: 23.07.2025 09:48:50 | BI1: Message | BJ1: 24.07.2025 02:30:17 | BK1: Message | BL1: 24.07.2025 07:10:05 | BM1: Message | BN1: 24.07.2025 15:47:38 | BO1: Message | BP1: 24.07.2025 15:57:20 | BQ1: Message | BR1: 24.07.2025 17:55:15 | BS1: Message | BT1: 24.07.2025 19:37:23 | BU1: Message | BV1: 24.07.2025 23:36:24 | BW1: Message | BX1: 05.08.2025 16:09:15 | BY1: Message | BZ1: 05.08.2025 16:15:04 | CA1: Message | CB1: 05.08.2025 16:22:04 | CC1: Message | CD1: 05.08.2025 16:43:41 | CE1: Message | CF1: 05.08.2025 17:02:04 | CG1: Message | CH1: 05.08.2025 17:20:58 | CI1: Message | CJ1: 09.08.2025 04:54:00 | CK1: Message | CL1: 09.08.2025 14:38:53 | CM1: Message | CN1: 09.08.2025 21:56:15 | CO1: Message | CP1: 18.08.2025 15:31:20 | CQ1: Message | CR1: 20.08.2025 10:02:58 | CS1: Message | CT1: 24.08.2025 15:36:50 | CU1: Message | CV1: 26.08.2025 11:41:22 | CW1: Message | CX1: 26.08.2025 13:36:43 | CY1: Message | CZ1: 26.08.2025 16:55:49 | DA1: Message | DB1: 30.10.2025 03:23:00 | DC1: Message | DD1: 03.11.2025 13:58:05 | DE1: Message
A2: 1 | B2: L00_URLAventis | C2: ='001a'!B59 -> {"url":p.aventisURL} | T2: 3063 | U2: 1257 | V2: =U2/$T2 -> 0.41038198 | X2: 1232 | Z2: 808 | AB2: 812 | AD2: 1260 | AF2: 1167 | AH2: 1292 | AI2: =AH2/$T2 -> 0.42180868 | AJ2: 1857 | AK2: =AJ2/$T2 -> 0.60626836 | AL2: 1313 | AM2: =AL2/$T2 -> 0.42866471 | AN2: 2008 | AO2: =AN2/$T2 -> 0.65556644 | AP2: 1711 | AQ2: =AP2/$T2 -> 0.55860268 | AR2: 1108 | AS2: =AR2/$T2 -> 0.36173686 | AT2: 1035 | AU2: =AT2/$T2 -> 0.33790402 | AV2: 925 | AW2: =AV2/$T2 -> 0.30199151 | AX2: 775 | AY2: =AX2/$T2 -> 0.25301992 | AZ2: 1532 | BB2: 606 | BD2: 1190 | BF2: 826 | BH2: 943 | BJ2: 913 | BL2: 966 | BN2: 680 | BP2: 1429 | BR2: 786 | BT2: 861 | BV2: 826 | BX2: 1630 | BZ2: 1666 | CB2: 1701 | CD2: 1482 | CF2: 1623 | CH2: 1615 | CJ2: 1643 | CL2: 1574 | CN2: 1630 | CP2: 887 | CR2: 876 | CT2: 1644 | CV2: 879 | CX2: 907 | CZ2: 877 | DB2: 857 | DD2: 559
A3: 3 | B3: M01_LoginMSOnline | C3: {"username":"aventis-test-aml@diartis.ch","password":"E7Qr=3cTiz$8Q!","fullname":"Test AmtsleiterIn Aventis","team":"Superuser"} | T3: 7444 | U3: 8520 | V3: =U3/$T3 -> 1.1445459 | X3: 4903 | Z3: 5580 | AB3: 5670 | AD3: 7847 | AF3: 7797 | AH3: 8584 | AI3: =AH3/$T3 -> 1.1531435 | AJ3: 10657 | AK3: =AJ3/$T3 -> 1.4316228 | AL3: 6184 | AM3: =AL3/$T3 -> 0.83073616 | AN3: 9052 | AO3: =AN3/$T3 -> 1.2160129 | AP3: 9966 | AQ3: =AP3/$T3 -> 1.3387963 | AR3: 9882 | AS3: =AR3/$T3 -> 1.3275121 | AT3: 11480 | AU3: =AT3/$T3 -> 1.5421816 | AV3: 4115 | AW3: =AV3/$T3 -> 0.5527942 | AX3: 4455 | AY3: =AX3/$T3 -> 0.59846857 | AZ3: 5668 | BB3: 3456 | BD3: 7938 | BF3: 8216 | BH3: 7025 | BJ3: 6381 | BL3: 4986 | BN3: 6752 | BP3: 7092 | BR3: 5294 | BT3: 5692 | BV3: 6212 | BX3: 5490 | BZ3: 5038 | CB3: 6857 | CD3: 5431 | CF3: 6550 | CH3: 5365 | CJ3: 5553 | CL3: 6093 | CN3: 5638 | CP3: 5456 | CR3: 8101 | CT3: 8444 | CV3: 7435 | CX3: 6390 | CZ3: 7346 | DB3: 8137 | DD3: 6289
A4: 4 | B4: L05_Check_VersionNumber | C4: =E4 -> {"username":"Bern.Sachbearbeiterin@diartis.ch","password":"XXxa22?pdTA66-S@","url":p.AventisURL,"version":"2025.5.275-stable"} | D4: Yes | E4: =F4&G4&H4&I4&J4&K4&L4&M4&N4&O4&P4 -> {"username":"Bern.Sachbearbeiterin@diartis.ch","password":"XXxa22?pdTA66-S@","url":p.AventisURL,"version":"2025.5.275-stable"} | F4: {"username":" | G4: Bern.Sachbearbeiterin@diartis.ch | H4: ","password":" | I4: XXxa22?pdTA66-S@ | J4: ","url": | K4: p.AventisURL | L4: ,"version":" | M4: 2025.5.275-stable | N4: "} | R4: seriell | T4: 447 | U4: 0 | V4: =U4/$T4 -> 0 | X4: 800 | Z4: 999 | AB4: 951 | AD4: 1044 | AF4: 911 | AH4: 0 | AI4: =AH4/$T4 -> 0 | AJ4: 542 | AK4: =AJ4/$T4 -> 1.212528 | AL4: 312 | AM4: =AL4/$T4 -> 0.69798658 | AN4: 317 | AO4: =AN4/$T4 -> 0.70917226 | AP4: 354 | AQ4: =AP4/$T4 -> 0.79194631 | AR4: 369 | AS4: =AR4/$T4 -> 0.82550336 | AT4: 283 | AU4: =AT4/$T4 -> 0.63310962 | AV4: 808 | AW4: =AV4/$T4 -> 1.8076063 | AX4: 1103 | AY4: =AX4/$T4 -> 2.4675615 | AZ4: 908 | BB4: 691 | BD4: 901 | BF4: 1028 | BH4: 1047 | BJ4: 0 | BK4: Error: [31mTimed out 10000ms waiting for [39m[2mexpect([22m[31mlocator[39m[2m).[22mtoHaveText[2m([22m[32mexpected[39m[2m)[22mLocator: locator('div.versions-container.ng-star-inserted').locator('span.version-row')Expected string: [32m"2025.4.[7m48[27m-dev"[39mReceived string: [31m"2025.4.[7m141[27m-dev"[39mCall log:[2m - Expect "soft toHaveText" with timeout 10000ms[22m[2m - waiting for locator('div.versions-container.ng-star-inserted').locator('span.version-row')[22m[2m 12 × locator resolved to <span class="version-row" _ngcontent-ng-c3803718529="">2025.4.141-dev</span>[22m[2m - unexpected value "2025.4.141-dev"[22m Screenshots: C:\Aventis\Aventis_Playwright-\test-results\videos\006_KeyWords_Smoketest_V2-000-000-Microsoft-Edge\test-failed-1.png Videos: C:\Aventis\Aventis_Playwright-\test-results\videos\006_KeyWords_Smoketest_V2-000-000-Microsoft-Edge\video.webm | BL4: 462 | BN4: 868 | BP4: 817 | BR4: 406 | BT4: 664 | BV4: 468 | BX4: 666 | BZ4: 685 | CB4: 702 | CD4: 1155 | CF4: 729 | CH4: 639 | CJ4: 721 | CL4: 719 | CN4: 704 | CP4: 461 | CR4: 662 | CT4: 344 | CV4: 764 | CX4: 625 | CZ4: 595 | DB4: 0 | DC4: Error: [2mexpect([22m[31mlocator[39m[2m).[22mtoHaveText[2m([22m[32mexpected[39m[2m)[22m failedLocator: locator('div.versions-container.ng-star-inserted').locator('span.version-row')Expected: [32m"2025.5.249-dev"[39mTimeout: 10000msError: element(s) not foundCall log:[2m - Expect "soft toHaveText" with timeout 10000ms[22m[2m - waiting for locator('div.versions-container.ng-star-inserted').locator('span.version-row')[22m[2m 10 × locator resolved to <span class="version-row" _ngcontent-ng-c2680178628="">2025.5.275-stable</span>[22m[2m - unexpected value "2025.5.275-stable"[22m Screenshots: C:\Aventis_Playwright\test-results\videos\006_KeyWords_Smoketest_V2-000-000-Microsoft-Edge\test-failed-1.png | DD4: 318
R5: 5 Parallel
C6: Schritt eins und 2 sind eigentlich redundant - ist aber brauchbar so | M6: 2025.5.249-dev | R6: 10 Parallel
R7: 20 Parallel
C8: Versionsnummer muss angepasst werden | R8: 50 Parallel
C9: 2024.4.77.62-dev
C10: 2024.4.77.102-dev
C11: 2024.4.77.271-dev
C12: 2024.6.82.143-dev
C13: 2024.6.82.143-dev | D13: test
C14: 2024.6.83.16-dev | D14: dev
C15: 2024.6.82.143-dev
C16: 2025.1.84.76-dev
C17: 2025.1.85.55-dev
C18: 2025.1.85.63-dev
C19: 2025.1.85.129-dev
C20: 2025.2.87.104-dev
C21: 2025.2.88.113-dev
C22: 2025.3.112-dev
C23: 2025.4.48-dev
C24: 2025.4.141-dev
C25: 2025.4.244-dev
C26: 2025.4.385-stable
A27: SpeedFaktor | B27: 1

Sheet 001x
A1: Step | B1: Keyword | C1: Testdata | D1: Screenshot | E1: done | F1: video | G1: =4*60*1000*SpeedFaktor -> 240000 | H1: 300 | AH1: Testresult | AI1: 09.12.2024 | AK1: Testresult | AL1: 09.12.2024 | AM1: Hoch | AN1: 04.02.2025 | AO1: Hoch | AP1: 04.02.2025 13:50:39 | AQ1: Hoch | AR1: 28.03.2025 10:25:49 | AS1: Hoch | AT1: 31.03.2025 18:57:12 | AU1: Hoch | AV1: 01.04.2025 00:27:19 | AW1: Hoch | AX1: 01.04.2025 23:50:20 | AY1: Hoch | AZ1: 09.04.2025 14:35:45 | BA1: Message 09.04.2025 14:35:45 | BB1: 09.04.2025 20:54:34 | BC1: Hoch | BD1: 25.06.2025 19:45:42 | BE1: Hoch | BF1: 26.06.2025 08:23:51 | BG1: Hoch | BH1: 05.07.2025 02:04:53 | BI1: Hoch | BK1: 22.07.2025 05:11:20 | BL1: Hoch | BM1: 22.07.2025 09:53:01 | BN1: Hoch | BO1: 22.07.2025 15:36:51 | BP1: Hoch | BQ1: 22.07.2025 18:44:05 | BR1: Hoch | BS1: 22.07.2025 19:54:04 | BT1: Hoch | BU1: 22.07.2025 22:30:01 | BV1: Hoch | BW1: 23.07.2025 08:43:42 | BX1: Hoch | BY1: 23.07.2025 09:48:50 | BZ1: Hoch | CA1: 24.07.2025 02:30:17 | CB1: Hoch | CC1: 24.07.2025 15:47:38 | CD1: Hoch | CE1: 24.07.2025 17:55:15 | CF1: Hoch | CG1: 24.07.2025 19:37:23 | CH1: Hoch | CI1: 24.07.2025 23:36:24 | CJ1: Hoch | CK1: 05.08.2025 16:09:15 | CL1: Hoch | CM1: 05.08.2025 16:15:04 | CN1: Hoch | CO1: 05.08.2025 16:22:04 | CP1: Hoch | CQ1: 05.08.2025 16:43:41 | CR1: Hoch | CS1: 05.08.2025 17:02:04 | CT1: Hoch | CU1: 05.08.2025 17:20:58 | CV1: Hoch | CW1: 18.08.2025 15:31:20 | CX1: Hoch | CY1: 20.08.2025 10:02:58 | CZ1: Message | DA1: 24.08.2025 15:36:50 | DB1: Message | DC1: 26.08.2025 11:41:22 | DD1: Message | DE1: 26.08.2025 13:36:43 | DF1: Message | DG1: 26.08.2025 16:55:49 | DH1: Message
A2: 1 | B2: L00_URLAventis | C2: =B58 -> {"url":p.aventisURL} | E2: =F2&G2&H2&I2&J2&K2&L2&M2&N2&O2&P2&Q2&R2&S2&T2&U2&V2&W2&X2 -> {"url":"https://dev.aventis.swiss"} | F2: {"url":" | G2: https://dev.aventis.swiss | H2: "} | AI2: 2535 | AL2: 933 | AM2: =AL2/($AI2) -> 0.36804734 | AN2: 554 | AO2: =AN2/($AI2) -> 0.21854043 | AP2: 770 | AQ2: =AP2/($AI2) -> 0.30374753 | AR2: 382 | AS2: =AR2/($AI2) -> 0.15069034 | AT2: 555 | AU2: =AT2/($AI2) -> 0.21893491 | AV2: 356 | AW2: =AV2/($AI2) -> 0.14043393 | AX2: 355 | AY2: =AX2/($AI2) -> 0.14003945 | AZ2: 424 | BB2: 354 | BC2: =BB2/($AI2) -> 0.13964497 | BD2: 4014 | BE2: =BD2/($AI2) -> 1.583432 | BF2: 4014 | BG2: =BF2/($AI2) -> 1.583432 | BH2: 4011 | BI2: =BH2/($AI2) -> 1.5822485 | BK2: 338 | BL2: =BK2/($AI2) -> 0.13333333 | BM2: 299 | BN2: =BM2/($AI2) -> 0.11794872 | BO2: 331 | BP2: =BO2/($AI2) -> 0.13057199 | BQ2: 406 | BR2: =BQ2/($AI2) -> 0.16015779 | BS2: 356 | BT2: =BS2/($AI2) -> 0.14043393 | BU2: 295 | BV2: =BU2/($AI2) -> 0.11637081 | BW2: 291 | BX2: =BW2/($AI2) -> 0.1147929 | BY2: 367 | BZ2: =BY2/($AI2) -> 0.14477318 | CA2: 444 | CB2: =CA2/($AI2) -> 0.17514793 | CC2: 354 | CD2: =CC2/($AI2) -> 0.13964497 | CE2: 420 | CF2: =CE2/($AI2) -> 0.16568047 | CG2: 366 | CH2: =CG2/($AI2) -> 0.1443787 | CI2: 173 | CJ2: =CI2/($AI2) -> 0.068244576 | CK2: 1013 | CL2: =CK2/($AI2) -> 0.39960552 | CM2: 707 | CN2: =CM2/($AI2) -> 0.27889546 | CO2: 733 | CP2: =CO2/($AI2) -> 0.28915187 | CQ2: 1009 | CR2: =CQ2/($AI2) -> 0.39802761 | CS2: 953 | CT2: =CS2/($AI2) -> 0.37593688 | CU2: 1182 | CV2: =CU2/($AI2) -> 0.46627219 | CW2: 213 | CX2: =CW2/($AI2) -> 0.084023669 | CY2: 403 | DA2: 904 | DC2: 335 | DE2: 369 | DG2: 363
A3: 4 | B3: M01_LoginMSOnline | C3: =E3 -> {"username":"bern.sozialarbeiterin1a@diartis.ch","password":"SMze97-jkSJ59!F.","fullname":"Sozialarbeiterin 1A Bern","team":"Sozialarbeit Bern 1"} | E3: =F3&G3&H3&I3&J3&K3&L3&M3&N3&O3&P3&Q3&R3&S3&T3&U3&V3&W3&X3 -> {"username":"bern.sozialarbeiterin1a@diartis.ch","password":"SMze97-jkSJ59!F.","fullname":"Sozialarbeiterin 1A Bern","team":"Sozialarbeit Bern 1"} | F3: {"username":" | G3: bern.sozialarbeiterin1a@diartis.ch | H3: ","password":" | I3: SMze97-jkSJ59!F. | J3: ","fullname":" | K3: Sozialarbeiterin 1A Bern | L3: ","team":" | M3: Sozialarbeit Bern 1 | N3: "} | AI3: 407 | AJ3: seriell | AL3: 407 | AM3: =AL3/($AI3) -> 1 | AN3: 417 | AO3: =AN3/($AI3) -> 1.02457 | AP3: 412 | AQ3: =AP3/($AI3) -> 1.012285 | AR3: 421 | AS3: =AR3/($AI3) -> 1.034398 | AT3: 403 | AU3: =AT3/($AI3) -> 0.99017199 | AV3: 411 | AW3: =AV3/($AI3) -> 1.009828 | AX3: 1391 | AY3: =AX3/($AI3) -> 3.4176904 | AZ3: 1355 | BB3: 1177 | BC3: =BB3/($AI3) -> 2.8918919 | BD3: 410 | BE3: =BD3/($AI3) -> 1.007371 | BF3: 416 | BG3: =BF3/($AI3) -> 1.022113 | BH3: 404 | BI3: =BH3/($AI3) -> 0.99262899 | BK3: 413 | BL3: =BK3/($AI3) -> 1.014742 | BM3: 403 | BN3: =BM3/($AI3) -> 0.99017199 | BO3: 1161 | BP3: =BO3/($AI3) -> 2.8525799 | BQ3: 1183 | BR3: =BQ3/($AI3) -> 2.9066339 | BS3: 1170 | BT3: =BS3/($AI3) -> 2.8746929 | BU3: 1089 | BV3: =BU3/($AI3) -> 2.6756757 | BW3: 1108 | BX3: =BW3/($AI3) -> 2.7223587 | BY3: 1162 | BZ3: =BY3/($AI3) -> 2.8550369 | CA3: 1253 | CB3: =CA3/($AI3) -> 3.0786241 | CC3: 1022 | CD3: =CC3/($AI3) -> 2.5110565 | CE3: 1168 | CF3: =CE3/($AI3) -> 2.8697789 | CG3: 1042 | CH3: =CG3/($AI3) -> 2.5601966 | CI3: 774 | CJ3: =CI3/($AI3) -> 1.9017199 | CK3: 1476 | CL3: =CK3/($AI3) -> 3.6265356 | CM3: 1335 | CN3: =CM3/($AI3) -> 3.2800983 | CO3: 1310 | CP3: =CO3/($AI3) -> 3.2186732 | CQ3: 1597 | CR3: =CQ3/($AI3) -> 3.9238329 | CS3: 1493 | CT3: =CS3/($AI3) -> 3.6683047 | CU3: 1812 | CV3: =CU3/($AI3) -> 4.4520885 | CW3: 814 | CX3: =CW3/($AI3) -> 2 | CY3: 1180 | DA3: 1383 | DC3: 1128 | DE3: 1072 | DG3: 1124
B4: P01_Person_Search | C4: =E4 -> {"name":p.FamilyName1,"vorname":p.ManFirstName1,"ahvNumber":"","geburtsdatum":""} | E4: =F4&G4&H4&I4&J4&K4&L4&M4&N4&O4&P4&Q4&R4&S4&T4&U4&V4&W4&X4 -> {"name":p.FamilyName1,"vorname":p.ManFirstName1,"ahvNumber":"","geburtsdatum":""} | F4: {"name": | G4: =G$63 -> p.FamilyName1 | H4: ,"vorname": | I4: =H$62 -> p.ManFirstName1 | J4: ,"ahvNumber":"" | L4: ,"geburtsdatum":" | N4: "} | AI4: 6791 | AJ4: 5 Parallel | AL4: 9630 | AM4: =AL4/($AI4) -> 1.4180533 | AN4: 8889 | AO4: =AN4/($AI4) -> 1.3089383 | AP4: 10209 | AQ4: =AP4/($AI4) -> 1.5033132 | AR4: 9507 | AS4: =AR4/($AI4) -> 1.3999411 | AT4: 6454 | AU4: =AT4/($AI4) -> 0.9503755 | AV4: 8318 | AW4: =AV4/($AI4) -> 1.2248564 | AX4: 10072 | AY4: =AX4/($AI4) -> 1.4831394 | AZ4: 10056 | BB4: 9423 | BC4: =BB4/($AI4) -> 1.3875718 | BD4: 6604 | BE4: =BD4/($AI4) -> 0.97246355 | BF4: 10404 | BG4: =BF4/($AI4) -> 1.5320277 | BH4: 4702 | BI4: =BH4/($AI4) -> 0.69238698 | BK4: 7245 | BL4: =BK4/($AI4) -> 1.0668532 | BM4: 6500 | BN4: =BM4/($AI4) -> 0.95714917 | BO4: 7445 | BP4: =BO4/($AI4) -> 1.0963039 | BQ4: 7658 | BR4: =BQ4/($AI4) -> 1.127669 | BS4: 6851 | BT4: =BS4/($AI4) -> 1.0088352 | BU4: 7556 | BV4: =BU4/($AI4) -> 1.1126491 | BW4: 7074 | BX4: =BW4/($AI4) -> 1.0416728 | BY4: 7362 | BZ4: =BY4/($AI4) -> 1.0840819 | CA4: 6882 | CB4: =CA4/($AI4) -> 1.0134001 | CC4: 7465 | CD4: =CC4/($AI4) -> 1.099249 | CE4: 7303 | CF4: =CE4/($AI4) -> 1.0753939 | CG4: 6858 | CH4: =CG4/($AI4) -> 1.009866 | CI4: 5092 | CJ4: =CI4/($AI4) -> 0.74981593 | CK4: 6341 | CL4: =CK4/($AI4) -> 0.93373583 | CM4: 6443 | CN4: =CM4/($AI4) -> 0.94875571 | CO4: 6003 | CP4: =CO4/($AI4) -> 0.88396407 | CQ4: 6485 | CR4: =CQ4/($AI4) -> 0.95494036 | CS4: 10819 | CT4: =CS4/($AI4) -> 1.593138 | CU4: 6713 | CV4: =CU4/($AI4) -> 0.98851421 | CW4: 5703 | CX4: =CW4/($AI4) -> 0.83978795 | CY4: 8793 | DA4: 6465 | DC4: 8399 | DE4: 7518 | DG4: 8015
A5: 6 | B5: P05_Person_Create_Manual_Complete | C5: =E5 -> {"name":p.FamilyName1,"vorname":p.ManFirstName1,"ahvNumber":p.AHVNumber1,"language":"Deutsch","zivilstand":"ledig","geburtsdatum":p.BirthdayAdult1,"national":"Schweiz","gender":"männlich","aufenthalt":""} | E5: =F5&G5&H5&I5&J5&K5&L5&M5&N5&O5&P5&Q5&R5&S5&T5&U5&V5&W5&X5 -> {"name":p.FamilyName1,"vorname":p.ManFirstName1,"ahvNumber":p.AHVNumber1,"language":"Deutsch","zivilstand":"ledig","geburtsdatum":p.BirthdayAdult1,"national":"Schweiz","gender":"männlich","aufenthalt":""} | F5: {"name": | G5: =G4 -> p.FamilyName1 | H5: ,"vorname": | I5: =I4 -> p.ManFirstName1 | J5: ,"ahvNumber": | K5: =I$62 -> p.AHVNumber1 | L5: ,"language":" | M5: Deutsch | N5: ","zivilstand":" | O5: ledig | P5: ","geburtsdatum": | Q5: =J62 -> p.BirthdayAdult1 | R5: ,"national":" | S5: Schweiz | T5: ","gender":" | U5: männlich | V5: ","aufenthalt":" | X5: "} | AI5: 4248 | AJ5: 10 Parallel | AL5: 2994 | AM5: =AL5/($AI5) -> 0.70480226 | AN5: 3290 | AO5: =AN5/($AI5) -> 0.77448211 | AP5: 3368 | AQ5: =AP5/($AI5) -> 0.79284369 | AR5: 3306 | AS5: =AR5/($AI5) -> 0.77824859 | AT5: 1785 | AU5: =AT5/($AI5) -> 0.42019774 | AV5: 3248 | AW5: =AV5/($AI5) -> 0.7645951 | AX5: 3124 | AY5: =AX5/($AI5) -> 0.7354049 | AZ5: 2770 | BB5: 2828 | BC5: =BB5/($AI5) -> 0.66572505 | BD5: 1839 | BE5: =BD5/($AI5) -> 0.4329096 | BF5: 3591 | BG5: =BF5/($AI5) -> 0.84533898 | BH5: 1286 | BI5: =BH5/($AI5) -> 0.3027307 | BK5: 1866 | BL5: =BK5/($AI5) -> 0.43926554 | BM5: 1734 | BN5: =BM5/($AI5) -> 0.40819209 | BO5: 1743 | BP5: =BO5/($AI5) -> 0.41031073 | BQ5: 1989 | BR5: =BQ5/($AI5) -> 0.46822034 | BS5: 1938 | BT5: =BS5/($AI5) -> 0.45621469 | BU5: 1806 | BV5: =BU5/($AI5) -> 0.42514124 | BW5: 1746 | BX5: =BW5/($AI5) -> 0.41101695 | BY5: 1735 | BZ5: =BY5/($AI5) -> 0.4084275 | CA5: 1625 | CB5: =CA5/($AI5) -> 0.38253296 | CC5: 1839 | CD5: =CC5/($AI5) -> 0.4329096 | CE5: 1633 | CF5: =CE5/($AI5) -> 0.3844162 | CG5: 1427 | CH5: =CG5/($AI5) -> 0.33592279 | CI5: 569 | CJ5: =CI5/($AI5) -> 0.13394539 | CK5: 459 | CL5: =CK5/($AI5) -> 0.10805085 | CM5: 1317 | CN5: =CM5/($AI5) -> 0.31002825 | CO5: 1435 | CP5: =CO5/($AI5) -> 0.33780603 | CQ5: 1356 | CR5: =CQ5/($AI5) -> 0.31920904 | CS5: 1454 | CT5: =CS5/($AI5) -> 0.34227872 | CU5: 1334 | CV5: =CU5/($AI5) -> 0.31403013 | CW5: 1162 | CX5: =CW5/($AI5) -> 0.27354049 | CY5: 1488 | DA5: 484 | DC5: 1126 | DE5: 1206 | DG5: 1425
A6: 7 | B6: P10_Person_Communikation_Complete | C6: =E6 -> {"mobile":"079 5413355","privateNumber":"079 5309370","email":"5624abc@gmail.com"} | E6: =F6&G6&H6&I6&J6&K6&L6&M6&N6&O6&P6&Q6&R6&S6&T6&U6&V6&W6&X6 -> {"mobile":"079 5413355","privateNumber":"079 5309370","email":"5624abc@gmail.com"} | F6: {"mobile":" | G6: ="079 "&RANDBETWEEN(5234500,5699999) -> 079 5413355 | H6: ","privateNumber":" | I6: ="079 "&RANDBETWEEN(5234500,5699999) -> 079 5309370 | J6: ","email":" | K6: 5624abc@gmail.com | L6: "} | AI6: 3639 | AJ6: 20 Parallel | AL6: 3657 | AM6: =AL6/($AI6) -> 1.0049464 | AN6: 4534 | AO6: =AN6/($AI6) -> 1.2459467 | AP6: 4999 | AQ6: =AP6/($AI6) -> 1.373729 | AR6: 4750 | AS6: =AR6/($AI6) -> 1.3053037 | AT6: 2507 | AU6: =AT6/($AI6) -> 0.68892553 | AV6: 4176 | AW6: =AV6/($AI6) -> 1.147568 | AX6: 3909 | AY6: =AX6/($AI6) -> 1.0741962 | AZ6: 3585 | BB6: 3326 | BC6: =BB6/($AI6) -> 0.91398736 | BD6: 3008 | BE6: =BD6/($AI6) -> 0.82660071 | BF6: 4148 | BG6: =BF6/($AI6) -> 1.1398736 | BH6: 2528 | BI6: =BH6/($AI6) -> 0.69469635 | BK6: 3014 | BL6: =BK6/($AI6) -> 0.82824952 | BM6: 2617 | BN6: =BM6/($AI6) -> 0.71915361 | BO6: 2785 | BP6: =BO6/($AI6) -> 0.76532014 | BQ6: 3146 | BR6: =BQ6/($AI6) -> 0.86452322 | BS6: 3792 | BT6: =BS6/($AI6) -> 1.0420445 | BU6: 3891 | BV6: =BU6/($AI6) -> 1.0692498 | BW6: 3784 | BX6: =BW6/($AI6) -> 1.0398461 | BY6: 3631 | BZ6: =BY6/($AI6) -> 0.99780159 | CA6: 2395 | CB6: =CA6/($AI6) -> 0.65814784 | CC6: 3816 | CD6: =CC6/($AI6) -> 1.0486397 | CE6: 2687 | CF6: =CE6/($AI6) -> 0.73838967 | CG6: 2464 | CH6: =CG6/($AI6) -> 0.6771091 | CI6: 2247 | CJ6: =CI6/($AI6) -> 0.61747733 | CK6: 2207 | CL6: =CK6/($AI6) -> 0.6064853 | CM6: 2514 | CN6: =CM6/($AI6) -> 0.69084913 | CO6: 2449 | CP6: =CO6/($AI6) -> 0.67298708 | CQ6: 2560 | CR6: =CQ6/($AI6) -> 0.70348997 | CS6: 2643 | CT6: =CS6/($AI6) -> 0.72629843 | CU6: 2534 | CV6: =CU6/($AI6) -> 0.69634515 | CW6: 2486 | CX6: =CW6/($AI6) -> 0.68315471 | CY6: 2948 | DA6: 2208 | DC6: 2753 | DE6: 2659 | DG6: 2809
A7: 8 | B7: P15_Person_Adress | C7: =E7 -> {"zusatz":"","strasse":"Strasse_566","houseNumber":"5","ort":"3053 Münchenbuchsee","validDate":"01.01.2025"} | E7: =F7&G7&H7&I7&J7&K7&L7&M7&N7&O7&P7&Q7&R7&S7&T7&U7&V7&W7&X7 -> {"zusatz":"","strasse":"Strasse_566","houseNumber":"5","ort":"3053 Münchenbuchsee","validDate":"01.01.2025"} | F7: {"zusatz":" | H7: ","strasse":" | I7: ="Strasse_"&RANDBETWEEN(1,1000) -> Strasse_566 | J7: ","houseNumber":" | K7: =RANDBETWEEN(1,100) -> 5 | L7: ","ort":" | M7: 3053 Münchenbuchsee | N7: ","validDate":" | O7: ="01.01."&TEXT(TODAY(),"YYYY") -> 01.01.2025 | P7: "} | AI7: 434 | AJ7: 50 Parallel | AL7: 443 | AM7: =AL7/($AI7) -> 1.0207373 | AN7: 807 | AO7: =AN7/($AI7) -> 1.859447 | AP7: 785 | AQ7: =AP7/($AI7) -> 1.8087558 | AR7: 742 | AS7: =AR7/($AI7) -> 1.7096774 | AT7: 407 | AU7: =AT7/($AI7) -> 0.93778802 | AV7: 629 | AW7: =AV7/($AI7) -> 1.4493088 | AX7: 624 | AY7: =AX7/($AI7) -> 1.437788 | AZ7: 547 | BB7: 428 | BC7: =BB7/($AI7) -> 0.98617512 | BD7: 246 | BE7: =BD7/($AI7) -> 0.56682028 | BF7: 641 | BG7: =BF7/($AI7) -> 1.4769585 | BH7: 247 | BI7: =BH7/($AI7) -> 0.56912442 | BK7: 358 | BL7: =BK7/($AI7) -> 0.82488479 | BM7: 344 | BN7: =BM7/($AI7) -> 0.79262673 | BO7: 321 | BP7: =BO7/($AI7) -> 0.73963134 | BQ7: 400 | BR7: =BQ7/($AI7) -> 0.92165899 | BS7: 509 | BT7: =BS7/($AI7) -> 1.1728111 | BU7: 513 | BV7: =BU7/($AI7) -> 1.1820276 | BW7: 456 | BX7: =BW7/($AI7) -> 1.0506912 | BY7: 457 | BZ7: =BY7/($AI7) -> 1.0529954 | CA7: 366 | CB7: =CA7/($AI7) -> 0.84331797 | CC7: 422 | CD7: =CC7/($AI7) -> 0.97235023 | CE7: 346 | CF7: =CE7/($AI7) -> 0.79723502 | CG7: 294 | CH7: =CG7/($AI7) -> 0.67741935 | CI7: 174 | CJ7: =CI7/($AI7) -> 0.40092166 | CK7: 148 | CL7: =CK7/($AI7) -> 0.34101382 | CM7: 240 | CN7: =CM7/($AI7) -> 0.55299539 | CO7: 234 | CP7: =CO7/($AI7) -> 0.53917051 | CQ7: 248 | CR7: =CQ7/($AI7) -> 0.57142857 | CS7: 224 | CT7: =CS7/($AI7) -> 0.51612903 | CU7: 252 | CV7: =CU7/($AI7) -> 0.58064516 | CW7: 175 | CX7: =CW7/($AI7) -> 0.40322581 | CY7: 403 | DA7: 151 | DC7: 237 | DE7: 293 | DG7: 325
A8: 9 | B8: P20_Person_ZahlungsVerbindung | C8: =E8 -> {"iban":p.IBAN1} | E8: =F8&G8&H8&I8&J8&K8&L8&M8&N8&O8&P8&Q8&R8&S8&T8&U8&V8&W8&X8 -> {"iban":p.IBAN1} | F8: {"iban": | G8: p.IBAN1 | H8: } | AI8: 5206 | AL8: 5243 | AM8: =AL8/($AI8) -> 1.0071072 | AN8: 5874 | AO8: =AN8/($AI8) -> 1.1283135 | AP8: 5927 | AQ8: =AP8/($AI8) -> 1.138494 | AR8: 5864 | AS8: =AR8/($AI8) -> 1.1263926 | AT8: 5028 | AU8: =AT8/($AI8) -> 0.96580868 | AV8: 5359 | AW8: =AV8/($AI8) -> 1.0293892 | AX8: 5610 | AY8: =AX8/($AI8) -> 1.0776028 | AZ8: 5301 | BB8: 5109 | BC8: =BB8/($AI8) -> 0.98136765 | BD8: 4704 | BE8: =BD8/($AI8) -> 0.9035728 | BF8: 5426 | BG8: =BF8/($AI8) -> 1.0422589 | BH8: 4624 | BI8: =BH8/($AI8) -> 0.88820592 | BK8: 4951 | BL8: =BK8/($AI8) -> 0.95101806 | BM8: 4775 | BN8: =BM8/($AI8) -> 0.91721091 | BO8: 4813 | BP8: =BO8/($AI8) -> 0.92451018 | BQ8: 5016 | BR8: =BQ8/($AI8) -> 0.96350365 | BS8: 5090 | BT8: =BS8/($AI8) -> 0.97771802 | BU8: 4875 | BV8: =BU8/($AI8) -> 0.93641952 | BW8: 5143 | BX8: =BW8/($AI8) -> 0.98789858 | BY8: 5098 | BZ8: =BY8/($AI8) -> 0.97925471 | CA8: 4840 | CB8: =CA8/($AI8) -> 0.9296965 | CC8: 5137 | CD8: =CC8/($AI8) -> 0.98674606 | CE8: 4898 | CF8: =CE8/($AI8) -> 0.9408375 | CG8: 4725 | CH8: =CG8/($AI8) -> 0.90760661 | CI8: 4511 | CJ8: =CI8/($AI8) -> 0.86650019 | CK8: 4489 | CL8: =CK8/($AI8) -> 0.8622743 | CM8: 4613 | CN8: =CM8/($AI8) -> 0.88609297 | CO8: 4618 | CP8: =CO8/($AI8) -> 0.8870534 | CQ8: 4611 | CR8: =CQ8/($AI8) -> 0.8857088 | CS8: 4609 | CT8: =CS8/($AI8) -> 0.88532463 | CU8: 4684 | CV8: =CU8/($AI8) -> 0.89973108 | CW8: 1637 | CX8: =CW8/($AI8) -> 0.31444487 | CY8: 2374 | DA8: 984 | DC8: 1361 | DE8: 1502 | DG8: 1728
A9: 10 | B9: P30_Person_Uebernehmen | AI9: 2108 | AL9: 2128 | AM9: =AL9/($AI9) -> 1.0094877 | AN9: 2253 | AO9: =AN9/($AI9) -> 1.0687856 | AP9: 2264 | AQ9: =AP9/($AI9) -> 1.0740038 | AR9: 2224 | AS9: =AR9/($AI9) -> 1.0550285 | AT9: 2165 | AU9: =AT9/($AI9) -> 1.0270398 | AV9: 2154 | AW9: =AV9/($AI9) -> 1.0218216 | AX9: 2204 | AY9: =AX9/($AI9) -> 1.0455408 | AZ9: 2132 | BB9: 2158 | BC9: =BB9/($AI9) -> 1.0237192 | BD9: 104 | BE9: =BD9/($AI9) -> 0.049335863 | BF9: 93 | BG9: =BF9/($AI9) -> 0.044117647 | BH9: 93 | BI9: =BH9/($AI9) -> 0.044117647 | BK9: 80 | BL9: =BK9/($AI9) -> 0.037950664 | BM9: 67 | BN9: =BM9/($AI9) -> 0.031783681 | BO9: 75 | BP9: =BO9/($AI9) -> 0.035578748 | BQ9: 87 | BR9: =BQ9/($AI9) -> 0.041271347 | BS9: 80 | BT9: =BS9/($AI9) -> 0.037950664 | BU9: 107 | BV9: =BU9/($AI9) -> 0.050759013 | BW9: 134 | BX9: =BW9/($AI9) -> 0.063567362 | BY9: 78 | BZ9: =BY9/($AI9) -> 0.037001898 | CA9: 55 | CB9: =CA9/($AI9) -> 0.026091082 | CC9: 62 | CD9: =CC9/($AI9) -> 0.029411765 | CE9: 83 | CF9: =CE9/($AI9) -> 0.039373814 | CG9: 69 | CH9: =CG9/($AI9) -> 0.032732448 | CI9: 74 | CJ9: =CI9/($AI9) -> 0.035104364 | CK9: 58 | CL9: =CK9/($AI9) -> 0.027514231 | CM9: 57 | CN9: =CM9/($AI9) -> 0.027039848 | CO9: 57 | CP9: =CO9/($AI9) -> 0.027039848 | CQ9: 54 | CR9: =CQ9/($AI9) -> 0.025616698 | CS9: 58 | CT9: =CS9/($AI9) -> 0.027514231 | CU9: 55 | CV9: =CU9/($AI9) -> 0.026091082 | CW9: 61 | CX9: =CW9/($AI9) -> 0.028937381 | CY9: 147 | DA9: 79 | DC9: 104 | DE9: 121 | DG9: 150
A10: 11 | B10: H01_Haushalt_Uebernehmen_Zustaendigkeit | C10: =E10 -> {"zust_Gemeinde":"Münchenbuchsee","zust_SozTeam":"Sozialarbeit Bern 1","zust_SozMitarbeiter":"Bern Sozialarbeiterin 1A","zust_SachbTeam":"Sachbearbeitung Bern","zust_SachbMitarbeiter":"Bern Sachbearbeiterin"} | E10: =F10&G10&H10&I10&J10&K10&L10&M10&N10&O10&P10&Q10&R10&S10&T10&U10&V10&W10&X10 -> {"zust_Gemeinde":"Münchenbuchsee","zust_SozTeam":"Sozialarbeit Bern 1","zust_SozMitarbeiter":"Bern Sozialarbeiterin 1A","zust_SachbTeam":"Sachbearbeitung Bern","zust_SachbMitarbeiter":"Bern Sachbearbeiterin"} | F10: {"zust_Gemeinde":" | G10: Münchenbuchsee | H10: ","zust_SozTeam":" | I10: Sozialarbeit Bern 1 | J10: ","zust_SozMitarbeiter":" | K10: Bern Sozialarbeiterin 1A | L10: ","zust_SachbTeam":" | M10: Sachbearbeitung Bern | N10: ","zust_SachbMitarbeiter":" | O10: Bern Sachbearbeiterin | P10: "} | AI10: 565 | AJ10: QA | AL10: 227 | AM10: =AL10/($AI10) -> 0.40176991 | AN10: 510 | AO10: =AN10/($AI10) -> 0.90265487 | AP10: 511 | AQ10: =AP10/($AI10) -> 0.90442478 | AR10: 382 | AS10: =AR10/($AI10) -> 0.67610619 | AT10: 310 | AU10: =AT10/($AI10) -> 0.54867257 | AV10: 312 | AW10: =AV10/($AI10) -> 0.55221239 | AX10: 331 | AY10: =AX10/($AI10) -> 0.58584071 | AZ10: 160 | BB10: 192 | BC10: =BB10/($AI10) -> 0.33982301 | BD10: 1157 | BE10: =BD10/($AI10) -> 2.0477876 | BF10: 1275 | BG10: =BF10/($AI10) -> 2.2566372 | BH10: 1240 | BI10: =BH10/($AI10) -> 2.1946903 | BK10: 1219 | BL10: =BK10/($AI10) -> 2.1575221 | BM10: 2010 | BN10: =BM10/($AI10) -> 3.5575221 | BO10: 1166 | BP10: =BO10/($AI10) -> 2.0637168 | BQ10: 1218 | BR10: =BQ10/($AI10) -> 2.1557522 | BS10: 1187 | BT10: =BS10/($AI10) -> 2.100885 | BU10: 1174 | BV10: =BU10/($AI10) -> 2.0778761 | BW10: 1217 | BX10: =BW10/($AI10) -> 2.1539823 | BY10: 1162 | BZ10: =BY10/($AI10) -> 2.0566372 | CA10: 1386 | CB10: =CA10/($AI10) -> 2.4530973 | CC10: 1224 | CD10: =CC10/($AI10) -> 2.1663717 | CE10: 1191 | CF10: =CE10/($AI10) -> 2.1079646 | CG10: 1186 | CH10: =CG10/($AI10) -> 2.099115 | CI10: 1151 | CJ10: =CI10/($AI10) -> 2.0371681 | CK10: 1152 | CL10: =CK10/($AI10) -> 2.0389381 | CM10: 1164 | CN10: =CM10/($AI10) -> 2.060177 | CO10: 1181 | CP10: =CO10/($AI10) -> 2.0902655 | CQ10: 1144 | CR10: =CQ10/($AI10) -> 2.0247788 | CS10: 1161 | CT10: =CS10/($AI10) -> 2.0548673 | CU10: 1162 | CV10: =CU10/($AI10) -> 2.0566372 | CW10: 1194 | CX10: =CW10/($AI10) -> 2.1132743 | CY10: 1313 | DA10: 1142 | DC10: 1185 | DE10: 1210 | DG10: 1267
A11: 12 | B11: D01_Dossier_Eroeffnen | C11: =E11 -> {"dossierBezeichnung":p.DossierName1,"eroeffnetAm":"04.11.2025","dossierSprache":"Deutsch"} | E11: =F11&G11&H11&I11&J11&K11&L11&M11&N11&O11&P11&Q11&R11&S11&T11&U11&V11&W11&X11 -> {"dossierBezeichnung":p.DossierName1,"eroeffnetAm":"04.11.2025","dossierSprache":"Deutsch"} | F11: {"dossierBezeichnung": | G11: =G$62 -> p.DossierName1 | H11: ,"eroeffnetAm":" | I11: =TEXT(TEXT(TODAY(),"DD")&"."&TEXT(TODAY(),"MM")&"."&TEXT(TODAY(),"YYYY"),"DD.MM.YYYY") -> 04.11.2025 | J11: ","dossierSprache":" | K11: Deutsch | L11: "} | AI11: 3489 | AL11: 3700 | AM11: =AL11/($AI11) -> 1.0604758 | AN11: 4194 | AO11: =AN11/($AI11) -> 1.2020636 | AP11: 4214 | AQ11: =AP11/($AI11) -> 1.2077959 | AR11: 3773 | AS11: =AR11/($AI11) -> 1.0813987 | AT11: 3081 | AU11: =AT11/($AI11) -> 0.88306105 | AV11: 3350 | AW11: =AV11/($AI11) -> 0.9601605 | AX11: 3683 | AY11: =AX11/($AI11) -> 1.0556033 | AZ11: 4165 | BB11: 4143 | BC11: =BB11/($AI11) -> 1.1874463 | BD11: 3974 | BE11: =BD11/($AI11) -> 1.1390083 | BF11: 4600 | BG11: =BF11/($AI11) -> 1.3184293 | BH11: 3617 | BI11: =BH11/($AI11) -> 1.0366867 | BK11: 3983 | BL11: =BK11/($AI11) -> 1.1415878 | BM11: 3964 | BN11: =BM11/($AI11) -> 1.1361422 | BO11: 3973 | BP11: =BO11/($AI11) -> 1.1387217 | BQ11: 4033 | BR11: =BQ11/($AI11) -> 1.1559186 | BS11: 4113 | BT11: =BS11/($AI11) -> 1.1788478 | BU11: 3934 | BV11: =BU11/($AI11) -> 1.1275437 | BW11: 3743 | BX11: =BW11/($AI11) -> 1.0728002 | BY11: 3999 | BZ11: =BY11/($AI11) -> 1.1461737 | CA11: 3854 | CB11: =CA11/($AI11) -> 1.1046145 | CC11: 4219 | CD11: =CC11/($AI11) -> 1.209229 | CE11: 3977 | CF11: =CE11/($AI11) -> 1.1398682 | CG11: 4155 | CH11: =CG11/($AI11) -> 1.1908856 | CI11: 4192 | CJ11: =CI11/($AI11) -> 1.2014904 | CK11: 4325 | CL11: =CK11/($AI11) -> 1.2396102 | CM11: 4199 | CN11: =CM11/($AI11) -> 1.2034967 | CO11: 4214 | CP11: =CO11/($AI11) -> 1.2077959 | CQ11: 3978 | CR11: =CQ11/($AI11) -> 1.1401548 | CS11: 4207 | CT11: =CS11/($AI11) -> 1.2057896 | CU11: 4243 | CV11: =CU11/($AI11) -> 1.2161078 | CW11: 4067 | CX11: =CW11/($AI11) -> 1.1656635 | CY11: 4229 | DA11: 4044 | DC11: 4085 | DE11: 4121 | DG11: 4106
A12: 14 | B12: BW04_ZahlungsVerbindung_Freigeben | C12: =E12 -> {"dossierInstitution":p.DossierName1,"klientschaft":`${p.FamilyName1}, ${p.ManFirstName1}`,"buttonBewilligung":"Anfragen","checkStatus":"In Bearbeitung"} | E12: =F12&G12&H12&I12&J12&K12&L12&M12&N12&O12&P12&Q12&R12&S12&T12&U12&V12&W12&X12 -> {"dossierInstitution":p.DossierName1,"klientschaft":`${p.FamilyName1}, ${p.ManFirstName1}`,"buttonBewilligung":"Anfragen","checkStatus":"In Bearbeitung"} | F12: {"dossierInstitution": | G12: =G11 -> p.DossierName1 | H12: ,"klientschaft":` | I12: =I23 -> ${p.FamilyName1}, ${p.ManFirstName1} | J12: `,"buttonBewilligung":" | K12: Anfragen | L12: ","checkStatus":" | M12: In Bearbeitung | N12: "} | AI12: 1017 | AL12: 1012 | AM12: =AL12/($AI12) -> 0.99508358 | AN12: 1010 | AO12: =AN12/($AI12) -> 0.99311701 | AP12: 1013 | AQ12: =AP12/($AI12) -> 0.99606686 | AR12: 1021 | AS12: =AR12/($AI12) -> 1.0039331 | AT12: 1017 | AU12: =AT12/($AI12) -> 1 | AV12: 1012 | AW12: =AV12/($AI12) -> 0.99508358 | AX12: 1006 | AY12: =AX12/($AI12) -> 0.98918387 | AZ12: 1010 | BB12: 1011 | BC12: =BB12/($AI12) -> 0.99410029 | BD12: 1544 | BE12: =BD12/($AI12) -> 1.5181908 | BF12: 1115 | BG12: =BF12/($AI12) -> 1.0963618 | BH12: 1067 | BI12: =BH12/($AI12) -> 1.0491642 | BK12: 917 | BL12: =BK12/($AI12) -> 0.90167158 | BM12: 1533 | BN12: =BM12/($AI12) -> 1.5073746 | BO12: 1538 | BP12: =BO12/($AI12) -> 1.5122911 | BQ12: 1396 | BR12: =BQ12/($AI12) -> 1.3726647 | BS12: 900 | BT12: =BS12/($AI12) -> 0.88495575 | BU12: 914 | BV12: =BU12/($AI12) -> 0.89872173 | BW12: 1098 | BX12: =BW12/($AI12) -> 1.079646 | BY12: 941 | BZ12: =BY12/($AI12) -> 0.9252704 | CA12: 1066 | CB12: =CA12/($AI12) -> 1.0481809 | CC12: 1093 | CD12: =CC12/($AI12) -> 1.0747296 | CE12: 1629 | CF12: =CE12/($AI12) -> 1.6017699 | CG12: 952 | CH12: =CG12/($AI12) -> 0.93608653 | CI12: 1544 | CJ12: =CI12/($AI12) -> 1.5181908 | CK12: 1495 | CL12: =CK12/($AI12) -> 1.4700098 | CM12: 1464 | CN12: =CM12/($AI12) -> 1.439528 | CO12: 1522 | CP12: =CO12/($AI12) -> 1.4965585 | CQ12: 1520 | CR12: =CQ12/($AI12) -> 1.4945919 | CS12: 1481 | CT12: =CS12/($AI12) -> 1.4562439 | CU12: 1517 | CV12: =CU12/($AI12) -> 1.4916421 | CW12: 8953 | CX12: =CW12/($AI12) -> 8.8033432 | CY12: 5523 | DA12: 4299 | DC12: 5380 | DE12: 7390 | DG12: 9091
A13: 15 | B13: L03_LogoutAndLoginDiffAccount | C13: =E13 -> {"username":"Bern.Sachbearbeiterin@diartis.ch","password":"XXxa22?pdTA66-S@"} | E13: =F13&G13&H13&I13&J13&K13&L13&M13&N13&O13&P13&Q13&R13&S13&T13&U13&V13&W13&X13 -> {"username":"Bern.Sachbearbeiterin@diartis.ch","password":"XXxa22?pdTA66-S@"} | F13: {"username":" | G13: Bern.Sachbearbeiterin@diartis.ch | H13: ","password":" | I13: XXxa22?pdTA66-S@ | J13: "} | AI13: 12078 | AL13: 12419 | AM13: =AL13/($AI13) -> 1.0282332 | AN13: 12798 | AO13: =AN13/($AI13) -> 1.0596125 | AP13: 12935 | AQ13: =AP13/($AI13) -> 1.0709555 | AR13: 14401 | AS13: =AR13/($AI13) -> 1.1923332 | AT13: 13760 | AU13: =AT13/($AI13) -> 1.1392615 | AV13: 14182 | AW13: =AV13/($AI13) -> 1.174201 | AX13: 14251 | AY13: =AX13/($AI13) -> 1.1799139 | AZ13: 9685 | BB13: 9964 | BC13: =BB13/($AI13) -> 0.82497102 | BD13: 4009 | BE13: =BD13/($AI13) -> 0.33192582 | BF13: 4022 | BG13: =BF13/($AI13) -> 0.33300215 | BH13: 4012 | BI13: =BH13/($AI13) -> 0.3321742 | BK13: 4017 | BL13: =BK13/($AI13) -> 0.33258818 | BM13: 4020 | BN13: =BM13/($AI13) -> 0.33283656 | BO13: 11484 | BP13: =BO13/($AI13) -> 0.95081967 | BQ13: 10053 | BR13: =BQ13/($AI13) -> 0.83233979 | BS13: 11588 | BT13: =BS13/($AI13) -> 0.95943037 | BU13: 11166 | BV13: =BU13/($AI13) -> 0.92449081 | BW13: 11642 | BX13: =BW13/($AI13) -> 0.96390131 | BY13: 9693 | BZ13: =BY13/($AI13) -> 0.80253353 | CA13: 16101 | CB13: =CA13/($AI13) -> 1.3330849 | CC13: 9509 | CD13: =CC13/($AI13) -> 0.78729922 | CE13: 6931 | CF13: =CE13/($AI13) -> 0.57385329 | CG13: 6610 | CH13: =CG13/($AI13) -> 0.54727604 | CI13: 6177 | CJ13: =CI13/($AI13) -> 0.51142573 | CK13: 43627 | CL13: =CK13/($AI13) -> 3.6121047 | CM13: 32197 | CN13: =CM13/($AI13) -> 2.6657559 | CO13: 32138 | CP13: =CO13/($AI13) -> 2.660871 | CQ13: 17430 | CR13: =CQ13/($AI13) -> 1.4431197 | CS13: 27317 | CT13: =CS13/($AI13) -> 2.2617155 | CU13: 29239 | CV13: =CU13/($AI13) -> 2.4208478 | CW13: 20759 | CX13: =CW13/($AI13) -> 1.7187448 | CY13: 8304 | DA13: 8337 | DC13: 9721 | DE13: 11773 | DG13: 19902
A14: 17 | B14: BW04_ZahlungsVerbindung_Freigeben | C14: =E14 -> {"dossierInstitution":p.DossierName1,"klientschaft":`${p.FamilyName1}, ${p.ManFirstName1}`,"buttonBewilligung":"Bewilligen","checkStatus":"Bewilligt"} | E14: =F14&G14&H14&I14&J14&K14&L14&M14&N14&O14&P14&Q14&R14&S14&T14&U14&V14&W14&X14 -> {"dossierInstitution":p.DossierName1,"klientschaft":`${p.FamilyName1}, ${p.ManFirstName1}`,"buttonBewilligung":"Bewilligen","checkStatus":"Bewilligt"} | F14: {"dossierInstitution": | G14: ='001x'!$G$11 -> p.DossierName1 | H14: ,"klientschaft":` | I14: =I23 -> ${p.FamilyName1}, ${p.ManFirstName1} | J14: `,"buttonBewilligung":" | K14: Bewilligen | L14: ","checkStatus":" | M14: Bewilligt | N14: "} | AI14: 4790 | AL14: 5007 | AM14: =AL14/($AI14) -> 1.0453027 | AN14: 5015 | AO14: =AN14/($AI14) -> 1.0469729 | AP14: 5014 | AQ14: =AP14/($AI14) -> 1.0467641 | AR14: 5021 | AS14: =AR14/($AI14) -> 1.0482255 | AT14: 5014 | AU14: =AT14/($AI14) -> 1.0467641 | AV14: 5009 | AW14: =AV14/($AI14) -> 1.0457203 | AX14: 5004 | AY14: =AX14/($AI14) -> 1.0446764 | AZ14: 5018 | BB14: 5021 | BC14: =BB14/($AI14) -> 1.0482255 | BD14: 8626 | BE14: =BD14/($AI14) -> 1.8008351 | BF14: 8975 | BG14: =BF14/($AI14) -> 1.8736952 | BH14: 9664 | BI14: =BH14/($AI14) -> 2.0175365 | BK14: 8654 | BL14: =BK14/($AI14) -> 1.8066806 | BM14: 8903 | BN14: =BM14/($AI14) -> 1.8586639 | BO14: 10580 | BP14: =BO14/($AI14) -> 2.2087683 | BQ14: 9302 | BR14: =BQ14/($AI14) -> 1.9419624 | BS14: 9758 | BT14: =BS14/($AI14) -> 2.0371608 | BU14: 9814 | BV14: =BU14/($AI14) -> 2.0488518 | BW14: 10548 | BX14: =BW14/($AI14) -> 2.2020877 | BY14: 8948 | BZ14: =BY14/($AI14) -> 1.8680585 | CA14: 9461 | CB14: =CA14/($AI14) -> 1.9751566 | CC14: 9691 | CD14: =CC14/($AI14) -> 2.0231733 | CE14: 10751 | CF14: =CE14/($AI14) -> 2.2444676 | CG14: 9774 | CH14: =CG14/($AI14) -> 2.040501 | CI14: 10115 | CJ14: =CI14/($AI14) -> 2.111691 | CK14: 10077 | CL14: =CK14/($AI14) -> 2.1037578 | CM14: 9625 | CN14: =CM14/($AI14) -> 2.0093946 | CO14: 9869 | CP14: =CO14/($AI14) -> 2.060334 | CQ14: 8732 | CR14: =CQ14/($AI14) -> 1.8229645 | CS14: 10681 | CT14: =CS14/($AI14) -> 2.2298539 | CU14: 9851 | CV14: =CU14/($AI14) -> 2.0565762 | CW14: 9773 | CX14: =CW14/($AI14) -> 2.0402923 | CY14: 11811 | DA14: 12426 | DC14: 12341 | DE14: 12021 | DG14: 10831
A15: 18 | B15: L03_LogoutAndLoginDiffAccount | C15: {"username":"bern.sozialarbeiterin1a@diartis.ch","password":"SMze97-jkSJ59!F."} | E15: =F15&G15&H15&I15&J15&K15&L15&M15&N15&O15&P15&Q15&R15&S15&T15&U15&V15&W15&X15 -> {"username":"Bern.Sachbearbeiterin@diartis.ch","password":"XXxa22?pdTA66-S@"} | F15: {"username":" | G15: Bern.Sachbearbeiterin@diartis.ch | H15: ","password":" | I15: XXxa22?pdTA66-S@ | J15: "} | AI15: 12332 | AL15: 12730 | AM15: =AL15/($AI15) -> 1.0322738 | AN15: 12589 | AO15: =AN15/($AI15) -> 1.0208401 | AP15: 13286 | AQ15: =AP15/($AI15) -> 1.0773597 | AR15: 13640 | AS15: =AR15/($AI15) -> 1.1060655 | AT15: 13635 | AU15: =AT15/($AI15) -> 1.1056601 | AV15: 13688 | AW15: =AV15/($AI15) -> 1.1099578 | AX15: 26297 | AY15: =AX15/($AI15) -> 2.1324197 | AZ15: 10616 | BB15: 10362 | BC15: =BB15/($AI15) -> 0.840253 | BD15: 410 | BE15: =BD15/($AI15) -> 0.033246837 | BF15: 416 | BG15: =BF15/($AI15) -> 0.033733377 | BH15: 401 | BI15: =BH15/($AI15) -> 0.032517029 | BK15: 418 | BL15: =BK15/($AI15) -> 0.033895556 | BM15: 404 | BN15: =BM15/($AI15) -> 0.032760298 | BO15: 10163 | BP15: =BO15/($AI15) -> 0.82411612 | BQ15: 10128 | BR15: =BQ15/($AI15) -> 0.82127798 | BS15: 10432 | BT15: =BS15/($AI15) -> 0.84592929 | BU15: 10609 | BV15: =BU15/($AI15) -> 0.86028219 | BW15: 11196 | BX15: =BW15/($AI15) -> 0.90788193 | BY15: 10494 | BZ15: =BY15/($AI15) -> 0.85095686 | CA15: 8885 | CB15: =CA15/($AI15) -> 0.7204833 | CC15: 9805 | CD15: =CC15/($AI15) -> 0.79508596 | CE15: 8275 | CF15: =CE15/($AI15) -> 0.67101849 | CG15: 7229 | CH15: =CG15/($AI15) -> 0.58619851 | CI15: 5168 | CJ15: =CI15/($AI15) -> 0.41907233 | CK15: 14471 | CL15: =CK15/($AI15) -> 1.1734512 | CM15: 9363 | CN15: =CM15/($AI15) -> 0.75924424 | CO15: 9758 | CP15: =CO15/($AI15) -> 0.79127473 | CQ15: 8724 | CR15: =CQ15/($AI15) -> 0.70742783 | CS15: 9595 | CT15: =CS15/($AI15) -> 0.77805709 | CU15: 8421 | CV15: =CU15/($AI15) -> 0.68285761 | CW15: 13550 | CX15: =CW15/($AI15) -> 1.0987674 | CY15: 10640 | DA15: 7882 | DC15: 9028 | DE15: 9203 | DG15: 8945
A16: 20 | B16: DO11_Dossier_Search_Lupe | C16: =E16 -> {"searchDossierOrKlient":p.DossierName1,"resultType":"Dossiers"} | E16: =F16&G16&H16&I16&J16&K16&L16&M16&N16&O16&P16&Q16&R16&S16&T16&U16&V16&W16&X16 -> {"searchDossierOrKlient":p.DossierName1,"resultType":"Dossiers"} | F16: {"searchDossierOrKlient": | G16: ='001x'!$G$11 -> p.DossierName1 | H16: ,"resultType":" | I16: Dossiers | J16: "} | AI16: 5018 | AL16: 5017 | AM16: =AL16/($AI16) -> 0.99980072 | AN16: 5008 | AO16: =AN16/($AI16) -> 0.99800717 | AP16: 5007 | AQ16: =AP16/($AI16) -> 0.99780789 | AR16: 5010 | AS16: =AR16/($AI16) -> 0.99840574 | AT16: 5024 | AU16: =AT16/($AI16) -> 1.0011957 | AV16: 5005 | AW16: =AV16/($AI16) -> 0.99740933 | AX16: 5011 | AY16: =AX16/($AI16) -> 0.99860502 | AZ16: 5005 | BB16: 5022 | BC16: =BB16/($AI16) -> 1.0007971 | BD16: 8677 | BE16: =BD16/($AI16) -> 1.729175 | BF16: 10125 | BG16: =BF16/($AI16) -> 2.0177361 | BH16: 9485 | BI16: =BH16/($AI16) -> 1.8901953 | BK16: 9709 | BL16: =BK16/($AI16) -> 1.9348346 | BM16: 9970 | BN16: =BM16/($AI16) -> 1.9868473 | BO16: 9975 | BP16: =BO16/($AI16) -> 1.9878438 | BQ16: 10619 | BR16: =BQ16/($AI16) -> 2.1161817 | BS16: 9783 | BT16: =BS16/($AI16) -> 1.9495815 | BU16: 10225 | BV16: =BU16/($AI16) -> 2.0376644 | BW16: 10001 | BX16: =BW16/($AI16) -> 1.9930251 | BY16: 9332 | BZ16: =BY16/($AI16) -> 1.8597051 | CA16: 8820 | CB16: =CA16/($AI16) -> 1.7576724 | CC16: 10004 | CD16: =CC16/($AI16) -> 1.993623 | CE16: 9135 | CF16: =CE16/($AI16) -> 1.8204464 | CG16: 8970 | CH16: =CG16/($AI16) -> 1.7875648 | CI16: 9488 | CJ16: =CI16/($AI16) -> 1.8907931 | CK16: 8800 | CL16: =CK16/($AI16) -> 1.7536867 | CM16: 10321 | CN16: =CM16/($AI16) -> 2.0567955 | CO16: 9974 | CP16: =CO16/($AI16) -> 1.9876445 | CQ16: 9194 | CR16: =CQ16/($AI16) -> 1.8322041 | CS16: 9458 | CT16: =CS16/($AI16) -> 1.8848147 | CU16: 9693 | CV16: =CU16/($AI16) -> 1.9316461 | CW16: 10242 | CX16: =CW16/($AI16) -> 2.0410522 | CY16: 21509 | DA16: 11750 | DC16: 11493 | DE16: 13832 | DG16: 11881
A17: 21 | B17: WO32_01b_Wohnsituation_Haushalt_Wohnung_anpassen | C17: =E17 -> {"vermieter":"Graber Immobilien","wohnungsgrosse":"4 Zimmer","mietkosten":1200,"nebenkosten":100} | E17: =F17&G17&H17&I17&J17&K17&L17&M17&N17&O17&P17&Q17&R17&S17&T17&U17&V17&W17&X17 -> {"vermieter":"Graber Immobilien","wohnungsgrosse":"4 Zimmer","mietkosten":1200,"nebenkosten":100} | F17: {"vermieter":" | G17: Graber Immobilien | H17: ","wohnungsgrosse":" | I17: 4 Zimmer | J17: ","mietkosten": | K17: 1200 | L17: ,"nebenkosten": | M17: 100 | N17: } | AI17: 10549 | AL17: 10895 | AM17: =AL17/($AI17) -> 1.0327993 | AN17: 11011 | AO17: =AN17/($AI17) -> 1.0437956 | AP17: 11381 | AQ17: =AP17/($AI17) -> 1.07887 | AR17: 10897 | AS17: =AR17/($AI17) -> 1.0329889 | AT17: 11079 | AU17: =AT17/($AI17) -> 1.0502417 | AV17: 11119 | AW17: =AV17/($AI17) -> 1.0540336 | AX17: 10646 | AY17: =AX17/($AI17) -> 1.0091952 | AZ17: 2477 | BB17: 2456 | BC17: =BB17/($AI17) -> 0.23281828 | BD17: 5594 | BE17: =BD17/($AI17) -> 0.53028723 | BF17: 6235 | BG17: =BF17/($AI17) -> 0.59105128 | BH17: 5583 | BI17: =BH17/($AI17) -> 0.52924448 | BK17: 5890 | BL17: =BK17/($AI17) -> 0.55834676 | BM17: 6024 | BN17: =BM17/($AI17) -> 0.57104939 | BO17: 5965 | BP17: =BO17/($AI17) -> 0.56545644 | BQ17: 5840 | BR17: =BQ17/($AI17) -> 0.55360698 | BS17: 6394 | BT17: =BS17/($AI17) -> 0.6061238 | BU17: 6114 | BV17: =BU17/($AI17) -> 0.579581 | BW17: 6376 | BX17: =BW17/($AI17) -> 0.60441748 | BY17: 5946 | BZ17: =BY17/($AI17) -> 0.56365532 | CA17: 5882 | CB17: =CA17/($AI17) -> 0.5575884 | CC17: 5357 | CD17: =CC17/($AI17) -> 0.50782065 | CE17: 3013 | CF17: =CE17/($AI17) -> 0.28561949 | CG17: 3110 | CH17: =CG17/($AI17) -> 0.29481467 | CI17: 3362 | CJ17: =CI17/($AI17) -> 0.31870319 | CK17: 115554 | CL17: =CK17/($AI17) -> 10.954024 | CM17: 5494 | CN17: =CM17/($AI17) -> 0.52080766 | CO17: 5566 | CP17: =CO17/($AI17) -> 0.52763295 | CQ17: 5405 | CR17: =CQ17/($AI17) -> 0.51237084 | CS17: 4980 | CT17: =CS17/($AI17) -> 0.47208266 | CU17: 5271 | CV17: =CU17/($AI17) -> 0.49966821 | CW17: 6470 | CX17: =CW17/($AI17) -> 0.61332828 | CY17: 7151 | DA17: 5668 | DC17: 5046 | DE17: 5190 | DG17: 4642
B18: WO30_Wohnsituation_Haushalt_Person_Hinzufuegen | C18: =E18 -> {"name":p.FamilyName1,"vorname":p.WomanFirstName1,"geburtsdatum":p.BirthdayAdult2,"ahvNumber":p.AHVNumber2,"personInhausltVon":"01.11.2025","inHauslt":"Übernehmen","ereignis":"Eheschliessung"} | E18: =F18&G18&H18&I18&J18&K18&L18&M18&N18&O18&P18&Q18&R18&S18&T18&U18&V18&W18&X18 -> {"name":p.FamilyName1,"vorname":p.WomanFirstName1,"geburtsdatum":p.BirthdayAdult2,"ahvNumber":p.AHVNumber2,"personInhausltVon":"01.11.2025","inHauslt":"Übernehmen","ereignis":"Eheschliessung"} | F18: {"name": | G18: =G5 -> p.FamilyName1 | H18: ,"vorname": | I18: =H63 -> p.WomanFirstName1 | J18: ,"geburtsdatum": | K18: =J63 -> p.BirthdayAdult2 | L18: ,"ahvNumber": | M18: =I63 -> p.AHVNumber2 | N18: ,"personInhausltVon":" | O18: ="01."&MONTH(TODAY())&"."&YEAR(TODAY()) -> 01.11.2025 | P18: ","inHauslt":" | Q18: Übernehmen | R18: ","ereignis":" | S18: Eheschliessung | T18: "} | AI18: 2974 | AL18: 3318 | AM18: =AL18/($AI18) -> 1.1156691 | AN18: 5657 | AO18: =AN18/($AI18) -> 1.902152 | AP18: 4597 | AQ18: =AP18/($AI18) -> 1.5457297 | AR18: 5547 | AS18: =AR18/($AI18) -> 1.8651648 | AT18: 5738 | AU18: =AT18/($AI18) -> 1.929388 | AV18: 5121 | AW18: =AV18/($AI18) -> 1.7219233 | AX18: 5462 | AY18: =AX18/($AI18) -> 1.8365837 | AZ18: 5249 | BB18: 5670 | BC18: =BB18/($AI18) -> 1.9065232 | BD18: 3690 | BE18: =BD18/($AI18) -> 1.2407532 | BF18: 3513 | BG18: =BF18/($AI18) -> 1.1812374 | BH18: 3054 | BI18: =BH18/($AI18) -> 1.0268998 | BK18: 4065 | BL18: =BK18/($AI18) -> 1.366846 | BM18: 4042 | BN18: =BM18/($AI18) -> 1.3591123 | BO18: 4106 | BP18: =BO18/($AI18) -> 1.3806321 | BQ18: 4024 | BR18: =BQ18/($AI18) -> 1.3530599 | BS18: 3730 | BT18: =BS18/($AI18) -> 1.2542031 | BU18: 4153 | BV18: =BU18/($AI18) -> 1.3964358 | BW18: 4360 | BX18: =BW18/($AI18) -> 1.466039 | BY18: 3948 | BZ18: =BY18/($AI18) -> 1.327505 | CA18: 3595 | CB18: =CA18/($AI18) -> 1.2088097 | CC18: 3955 | CD18: =CC18/($AI18) -> 1.3298588 | CE18: 3966 | CF18: =CE18/($AI18) -> 1.3335575 | CG18: 3555 | CH18: =CG18/($AI18) -> 1.1953598 | CI18: 2862 | CJ18: =CI18/($AI18) -> 0.96234028 | CK18: 4854 | CL18: =CK18/($AI18) -> 1.6321453 | CM18: 3422 | CN18: =CM18/($AI18) -> 1.1506389 | CO18: 3054 | CP18: =CO18/($AI18) -> 1.0268998 | CQ18: 3169 | CR18: =CQ18/($AI18) -> 1.0655683 | CS18: 3240 | CT18: =CS18/($AI18) -> 1.0894418 | CU18: 7870 | CV18: =CU18/($AI18) -> 2.6462677 | CW18: 4264 | CX18: =CW18/($AI18) -> 1.4337592 | CY18: 4418 | DA18: 3437 | DC18: 3821 | DE18: 4217 | DG18: 3452
B19: WO30_Wohnsituation_Haushalt_Person_Hinzufuegen | C19: =E19 -> {"name":p.FamilyName1,"vorname":p.GirlFirstName1,"geburtsdatum":p.BirthdayKid1,"ahvNumber":p.AHVNumber3,"personInhausltVon":"01.11.2025","inHauslt":"Übernehmen","ereignis":"Geburt"} | E19: =F19&G19&H19&I19&J19&K19&L19&M19&N19&O19&P19&Q19&R19&S19&T19&U19&V19&W19&X19 -> {"name":p.FamilyName1,"vorname":p.GirlFirstName1,"geburtsdatum":p.BirthdayKid1,"ahvNumber":p.AHVNumber3,"personInhausltVon":"01.11.2025","inHauslt":"Übernehmen","ereignis":"Geburt"} | F19: {"name": | G19: =G18 -> p.FamilyName1 | H19: ,"vorname": | I19: =H64 -> p.GirlFirstName1 | J19: ,"geburtsdatum": | K19: =J64 -> p.BirthdayKid1 | L19: ,"ahvNumber": | M19: =I64 -> p.AHVNumber3 | N19: ,"personInhausltVon":" | O19: ="01."&MONTH(TODAY())&"."&YEAR(TODAY()) -> 01.11.2025 | P19: ","inHauslt":" | Q19: Übernehmen | R19: ","ereignis":" | S19: Geburt | T19: "} | AI19: 2228 | AL19: 2472 | AM19: =AL19/($AI19) -> 1.1095153 | AN19: 3858 | AO19: =AN19/($AI19) -> 1.7315978 | AP19: 4051 | AQ19: =AP19/($AI19) -> 1.8182226 | AR19: 5422 | AS19: =AR19/($AI19) -> 2.4335727 | AT19: 5458 | AU19: =AT19/($AI19) -> 2.4497307 | AV19: 5188 | AW19: =AV19/($AI19) -> 2.3285458 | AX19: 5482 | AY19: =AX19/($AI19) -> 2.4605027 | AZ19: 4093 | BB19: 4059 | BC19: =BB19/($AI19) -> 1.8218133 | BD19: 2309 | BE19: =BD19/($AI19) -> 1.0363555 | BF19: 2476 | BG19: =BF19/($AI19) -> 1.1113106 | BH19: 2375 | BI19: =BH19/($AI19) -> 1.0659785 | BK19: 2955 | BL19: =BK19/($AI19) -> 1.3263016 | BM19: 2440 | BN19: =BM19/($AI19) -> 1.0951526 | BO19: 2465 | BP19: =BO19/($AI19) -> 1.1063734 | BQ19: 2924 | BR19: =BQ19/($AI19) -> 1.3123878 | BS19: 2760 | BT19: =BS19/($AI19) -> 1.2387792 | BU19: 2703 | BV19: =BU19/($AI19) -> 1.2131957 | BW19: 2427 | BX19: =BW19/($AI19) -> 1.0893178 | BY19: 2623 | BZ19: =BY19/($AI19) -> 1.177289 | CA19: 2444 | CB19: =CA19/($AI19) -> 1.0969479 | CC19: 2660 | CD19: =CC19/($AI19) -> 1.1938959 | CE19: 2471 | CF19: =CE19/($AI19) -> 1.1090664 | CG19: 2297 | CH19: =CG19/($AI19) -> 1.0309695 | CI19: 2186 | CJ19: =CI19/($AI19) -> 0.98114901 | CK19: 2336 | CL19: =CK19/($AI19) -> 1.048474 | CM19: 2354 | CN19: =CM19/($AI19) -> 1.056553 | CO19: 2351 | CP19: =CO19/($AI19) -> 1.0552065 | CQ19: 2188 | CR19: =CQ19/($AI19) -> 0.98204668 | CS19: 3215 | CT19: =CS19/($AI19) -> 1.4429982 | CU19: 2269 | CV19: =CU19/($AI19) -> 1.0184022 | CW19: 1834 | CX19: =CW19/($AI19) -> 0.82315978 | CY19: 2491 | DA19: 3260 | DC19: 3227 | DE19: 3846 | DG19: 2698
B20: WO30_Wohnsituation_Haushalt_Person_Hinzufuegen | C20: =E20 -> {"name":p.FamilyName1,"vorname":p.ManFirstName2,"geburtsdatum":p.BirthdayKid2,"ahvNumber":p.AHVNumber4,"personInhausltVon":"01.11.2025","inHauslt":"Übernehmen","ereignis":"Geburt"} | E20: =F20&G20&H20&I20&J20&K20&L20&M20&N20&O20&P20&Q20&R20&S20&T20&U20&V20&W20&X20 -> {"name":p.FamilyName1,"vorname":p.ManFirstName2,"geburtsdatum":p.BirthdayKid2,"ahvNumber":p.AHVNumber4,"personInhausltVon":"01.11.2025","inHauslt":"Übernehmen","ereignis":"Geburt"} | F20: {"name": | G20: =G19 -> p.FamilyName1 | H20: ,"vorname": | I20: =H65 -> p.ManFirstName2 | J20: ,"geburtsdatum": | K20: =J65 -> p.BirthdayKid2 | L20: ,"ahvNumber": | M20: =I65 -> p.AHVNumber4 | N20: ,"personInhausltVon":" | O20: ="01."&MONTH(TODAY())&"."&YEAR(TODAY()) -> 01.11.2025 | P20: ","inHauslt":" | Q20: Übernehmen | R20: ","ereignis":" | S20: Geburt | T20: "} | AI20: 3768 | AL20: 3446 | AM20: =AL20/($AI20) -> 0.91454352 | AN20: 4686 | AO20: =AN20/($AI20) -> 1.2436306 | AP20: 4805 | AQ20: =AP20/($AI20) -> 1.2752123 | AR20: 5276 | AS20: =AR20/($AI20) -> 1.4002123 | AT20: 5353 | AU20: =AT20/($AI20) -> 1.4206476 | AV20: 5078 | AW20: =AV20/($AI20) -> 1.3476645 | AX20: 5490 | AY20: =AX20/($AI20) -> 1.4570064 | AZ20: 4861 | BB20: 4786 | BC20: =BB20/($AI20) -> 1.2701699 | BD20: 3176 | BE20: =BD20/($AI20) -> 0.84288747 | BF20: 2698 | BG20: =BF20/($AI20) -> 0.71602972 | BH20: 3130 | BI20: =BH20/($AI20) -> 0.83067941 | BK20: 3416 | BL20: =BK20/($AI20) -> 0.90658174 | BM20: 3782 | BN20: =BM20/($AI20) -> 1.0037155 | BO20: 3406 | BP20: =BO20/($AI20) -> 0.90392781 | BQ20: 3395 | BR20: =BQ20/($AI20) -> 0.90100849 | BS20: 3792 | BT20: =BS20/($AI20) -> 1.0063694 | BU20: 3454 | BV20: =BU20/($AI20) -> 0.91666667 | BW20: 2956 | BX20: =BW20/($AI20) -> 0.78450106 | BY20: 3073 | BZ20: =BY20/($AI20) -> 0.81555202 | CA20: 3289 | CB20: =CA20/($AI20) -> 0.87287686 | CC20: 2978 | CD20: =CC20/($AI20) -> 0.7903397 | CE20: 3031 | CF20: =CE20/($AI20) -> 0.80440552 | CG20: 3312 | CH20: =CG20/($AI20) -> 0.87898089 | CI20: 3241 | CJ20: =CI20/($AI20) -> 0.860138 | CK20: 6528 | CL20: =CK20/($AI20) -> 1.7324841 | CM20: 3389 | CN20: =CM20/($AI20) -> 0.89941614 | CO20: 3310 | CP20: =CO20/($AI20) -> 0.87845011 | CQ20: 3745 | CR20: =CQ20/($AI20) -> 0.99389597 | CS20: 8095 | CT20: =CS20/($AI20) -> 2.1483546 | CU20: 3351 | CV20: =CU20/($AI20) -> 0.88933121 | CW20: 3878 | CX20: =CW20/($AI20) -> 1.0291932 | CY20: 3723 | DA20: 3462 | DC20: 3841 | DE20: 3482 | DG20: 2962
A21: 20 | B21: DO11_Dossier_Search_Lupe | C21: =E21 -> {"searchDossierOrKlient":p.DossierName1,"resultType":"Dossiers"} | E21: =F21&G21&H21&I21&J21&K21&L21&M21&N21&O21&P21&Q21&R21&S21&T21&U21&V21&W21&X21 -> {"searchDossierOrKlient":p.DossierName1,"resultType":"Dossiers"} | F21: {"searchDossierOrKlient": | G21: ='001x'!$G$11 -> p.DossierName1 | H21: ,"resultType":" | I21: Dossiers | J21: "} | AI21: 5018 | AL21: 5017 | AM21: =AL21/($AI21) -> 0.99980072 | AN21: 5008 | AO21: =AN21/($AI21) -> 0.99800717 | AP21: 5007 | AQ21: =AP21/($AI21) -> 0.99780789 | AR21: 5223 | AS21: =AR21/($AI21) -> 1.0408529 | AT21: 5240 | AU21: =AT21/($AI21) -> 1.0442407 | AV21: 5055 | AW21: =AV21/($AI21) -> 1.0073735 | AX21: 5244 | AY21: =AX21/($AI21) -> 1.0450379 | AZ21: 4446 | BB21: 4534 | BC21: =BB21/($AI21) -> 0.90354723 | BD21: 2459 | BE21: =BD21/($AI21) -> 0.49003587 | BF21: 2627 | BG21: =BF21/($AI21) -> 0.52351534 | BH21: 2748 | BI21: =BH21/($AI21) -> 0.54762854 | BK21: 2980 | BL21: =BK21/($AI21) -> 0.5938621 | BM21: 8189 | BN21: =BM21/($AI21) -> 1.6319251 | BO21: 2925 | BP21: =BO21/($AI21) -> 0.58290155 | BQ21: 2789 | BR21: =BQ21/($AI21) -> 0.55579912 | BS21: 2861 | BT21: =BS21/($AI21) -> 0.57014747 | BU21: 2881 | BV21: =BU21/($AI21) -> 0.57413312 | BW21: 2922 | BX21: =BW21/($AI21) -> 0.58230371 | BY21: 2740 | BZ21: =BY21/($AI21) -> 0.54603428 | CA21: 3240 | CB21: =CA21/($AI21) -> 0.64567557 | CC21: 2640 | CD21: =CC21/($AI21) -> 0.52610602 | CE21: 3066 | CF21: =CE21/($AI21) -> 0.6110004 | CG21: 2531 | CH21: =CG21/($AI21) -> 0.50438422 | CI21: 2500 | CJ21: =CI21/($AI21) -> 0.49820646 | CK21: 3370 | CL21: =CK21/($AI21) -> 0.6715823 | CM21: 3339 | CN21: =CM21/($AI21) -> 0.66540454 | CO21: 3747 | CP21: =CO21/($AI21) -> 0.74671184 | CQ21: 4278 | CR21: =CQ21/($AI21) -> 0.85253089 | CS21: 3727 | CT21: =CS21/($AI21) -> 0.74272619 | CU21: 3740 | CV21: =CU21/($AI21) -> 0.74531686 | CW21: 3853 | CX21: =CW21/($AI21) -> 0.76783579 | CY21: 3583 | DA21: 2761 | DC21: 2974 | DE21: 2892 | DG21: 2781
B22: WO32_01b_Wohnsituation_Haushalt_Wohnung_anpassen | C22: =E22 -> {"vermieter":"Graber Immobilien","wohnungsgrosse":"4 Zimmer","mietkosten":3000,"nebenkosten":300} | E22: =F22&G22&H22&I22&J22&K22&L22&M22&N22&O22&P22&Q22&R22&S22&T22&U22&V22&W22&X22 -> {"vermieter":"Graber Immobilien","wohnungsgrosse":"4 Zimmer","mietkosten":3000,"nebenkosten":300} | F22: {"vermieter":" | G22: Graber Immobilien | H22: ","wohnungsgrosse":" | I22: 4 Zimmer | J22: ","mietkosten": | K22: 3000 | L22: ,"nebenkosten": | M22: 300 | N22: } | AI22: 2656 | AL22: 2912 | AM22: =AL22/($AI22) -> 1.0963855 | AN22: 4161 | AO22: =AN22/($AI22) -> 1.5666416 | AP22: 4394 | AQ22: =AP22/($AI22) -> 1.6543675 | AR22: 11040 | AS22: =AR22/($AI22) -> 4.1566265 | AT22: 11254 | AU22: =AT22/($AI22) -> 4.2371988 | AV22: 11193 | AW22: =AV22/($AI22) -> 4.2142319 | AX22: 10765 | AY22: =AX22/($AI22) -> 4.0530873 | AZ22: 3743 | BB22: 3727 | BC22: =BB22/($AI22) -> 1.403238 | BD22: 5066 | BE22: =BD22/($AI22) -> 1.9073795 | BF22: 5061 | BG22: =BF22/($AI22) -> 1.905497 | BH22: 4955 | BI22: =BH22/($AI22) -> 1.8655873 | BK22: 5193 | BL22: =BK22/($AI22) -> 1.9551958 | BM22: 6491 | BN22: =BM22/($AI22) -> 2.4439006 | BO22: 5502 | BP22: =BO22/($AI22) -> 2.0715361 | BQ22: 5250 | BR22: =BQ22/($AI22) -> 1.9766566 | BS22: 5454 | BT22: =BS22/($AI22) -> 2.0534639 | BU22: 5295 | BV22: =BU22/($AI22) -> 1.9935994 | BW22: 5422 | BX22: =BW22/($AI22) -> 2.0414157 | BY22: 5319 | BZ22: =BY22/($AI22) -> 2.0026355 | CA22: 5434 | CB22: =CA22/($AI22) -> 2.0459337 | CC22: 4937 | CD22: =CC22/($AI22) -> 1.8588102 | CE22: 2683 | CF22: =CE22/($AI22) -> 1.0101657 | CG22: 2278 | CH22: =CG22/($AI22) -> 0.85768072 | CI22: 2737 | CJ22: =CI22/($AI22) -> 1.030497 | CK22: 5151 | CL22: =CK22/($AI22) -> 1.9393825 | CM22: 5060 | CN22: =CM22/($AI22) -> 1.9051205 | CO22: 5018 | CP22: =CO22/($AI22) -> 1.8893072 | CQ22: 5676 | CR22: =CQ22/($AI22) -> 2.1370482 | CS22: 5499 | CT22: =CS22/($AI22) -> 2.0704066 | CU22: 5544 | CV22: =CU22/($AI22) -> 2.0873494 | CW22: 5403 | CX22: =CW22/($AI22) -> 2.034262 | CY22: 5391
B23: KL01_Klientschaft_select | C23: =E23 -> {"dossier":p.DossierName1,"klientschaft":`${p.FamilyName1}, ${p.ManFirstName1}`} | E23: =F23&G23&H23&I23&J23&K23&L23&M23&N23&O23&P23&Q23&R23&S23&T23&U23&V23&W23&X23 -> {"dossier":p.DossierName1,"klientschaft":`${p.FamilyName1}, ${p.ManFirstName1}`} | F23: {"dossier": | G23: =G11 -> p.DossierName1 | H23: ,"klientschaft":` | I23: ="${"&$G$4&"}, ${"&$I$4&"}" -> ${p.FamilyName1}, ${p.ManFirstName1} | J23: `} | AI23: 9006 | AL23: 9017 | AM23: =AL23/($AI23) -> 1.0012214 | AN23: 9018 | AO23: =AN23/($AI23) -> 1.0013324 | AP23: 9010 | AQ23: =AP23/($AI23) -> 1.0004441 | AR23: 5023 | AS23: =AR23/($AI23) -> 0.55773928 | AT23: 5019 | AU23: =AT23/($AI23) -> 0.55729514 | AV23: 5007 | AW23: =AV23/($AI23) -> 0.55596269 | AX23: 5020 | AY23: =AX23/($AI23) -> 0.55740617 | AZ23: 5005 | BB23: 5019 | BC23: =BB23/($AI23) -> 0.55729514 | BD23: 2737 | BE23: =BD23/($AI23) -> 0.30390851 | BF23: 2842 | BG23: =BF23/($AI23) -> 0.3155674 | BH23: 2719 | BI23: =BH23/($AI23) -> 0.30190984 | BK23: 2814 | BL23: =BK23/($AI23) -> 0.31245836 | BM23: 3135 | BN23: =BM23/($AI23) -> 0.34810127 | BO23: 2783 | BP23: =BO23/($AI23) -> 0.30901621 | BQ23: 2661 | BR23: =BQ23/($AI23) -> 0.29546969 | BS23: 2900 | BT23: =BS23/($AI23) -> 0.32200755 | BU23: 2926 | BV23: =BU23/($AI23) -> 0.32489451 | BW23: 2996 | BX23: =BW23/($AI23) -> 0.33266711 | BY23: 2749 | BZ23: =BY23/($AI23) -> 0.30524095 | CA23: 2685 | CB23: =CA23/($AI23) -> 0.29813458 | CC23: 2806 | CD23: =CC23/($AI23) -> 0.31157006 | CE23: 2927 | CF23: =CE23/($AI23) -> 0.32500555 | CG23: 2561 | CH23: =CG23/($AI23) -> 0.28436598 | CI23: 2736 | CJ23: =CI23/($AI23) -> 0.30379747 | CK23: 2636 | CL23: =CK23/($AI23) -> 0.29269376 | CM23: 3184 | CN23: =CM23/($AI23) -> 0.35354208 | CO23: 2566 | CP23: =CO23/($AI23) -> 0.28492116 | CQ23: 2392 | CR23: =CQ23/($AI23) -> 0.26560071 | CS23: 3157 | CT23: =CS23/($AI23) -> 0.35054408 | CU23: 3228 | CV23: =CU23/($AI23) -> 0.35842771 | CW23: 2712 | CX23: =CW23/($AI23) -> 0.30113258 | CY23: 2847 | DA23: 5812 | DC23: 5510 | DE23: 4776 | DG23: 4469
B24: E01_Delay | C24: {"Pause":"6000"} | AI24: 2011 | AL24: 2008 | AM24: =AL24/($AI24) -> 0.9985082 | AN24: 2011 | AO24: =AN24/($AI24) -> 1 | AQ24: =AP24/($AI24) -> 0 | AR24: 2013 | AS24: =AR24/($AI24) -> 1.0009945 | AT24: 2020 | AU24: =AT24/($AI24) -> 1.0044754 | AV24: 2017 | AW24: =AV24/($AI24) -> 1.0029836 | AX24: 2019 | AY24: =AX24/($AI24) -> 1.0039781 | AZ24: 2013 | BB24: 341 | BC24: =BB24/($AI24) -> 0.16956738 | BD24: 2007 | BE24: =BD24/($AI24) -> 0.99801094 | BF24: 2003 | BG24: =BF24/($AI24) -> 0.99602188 | BH24: 2009 | BI24: =BH24/($AI24) -> 0.99900547 | BK24: 2019 | BL24: =BK24/($AI24) -> 1.0039781 | BM24: 2008 | BN24: =BM24/($AI24) -> 0.9985082 | BO24: 2005 | BP24: =BO24/($AI24) -> 0.99701641 | BQ24: 2012 | BR24: =BQ24/($AI24) -> 1.0004973 | BS24: 2004 | BT24: =BS24/($AI24) -> 0.99651914 | BU24: 2005 | BV24: =BU24/($AI24) -> 0.99701641 | BW24: 2013 | BX24: =BW24/($AI24) -> 1.0009945 | BY24: 2013 | BZ24: =BY24/($AI24) -> 1.0009945 | CA24: 2006 | CB24: =CA24/($AI24) -> 0.99751367 | CC24: 2006 | CD24: =CC24/($AI24) -> 0.99751367 | CE24: 2015 | CF24: =CE24/($AI24) -> 1.0019891 | CG24: 2010 | CH24: =CG24/($AI24) -> 0.99950273 | CI24: 2012 | CJ24: =CI24/($AI24) -> 1.0004973 | CK24: 2005 | CL24: =CK24/($AI24) -> 0.99701641 | CN24: =CM24/($AI24) -> 0 | CO24: 4190 | CP24: =CO24/($AI24) -> 2.0835405 | CQ24: 4228 | CR24: =CQ24/($AI24) -> 2.1024366 | CS24: 4085 | CT24: =CS24/($AI24) -> 2.0313277 | CU24: 4191 | CV24: =CU24/($AI24) -> 2.0840378 | CW24: 4489 | CX24: =CW24/($AI24) -> 2.2322228 | CY24: 5077
B25: KL03_ErwerbsituationEinnahmen_Lohn_erfassen | C25: =E25 -> {"zahlbarDurch":"BKW Energie AG","pensumm":"100","betrag":"1000","gueltigVon":"01.01.2025","gueltigBis":"31.12.2025","checkbox":"x"} | E25: =F25&G25&H25&I25&J25&K25&L25&M25&N25&O25&P25&Q25&R25&S25&T25&U25&V25&W25&X25 -> {"zahlbarDurch":"BKW Energie AG","pensumm":"100","betrag":"1000","gueltigVon":"01.01.2025","gueltigBis":"31.12.2025","checkbox":"x"} | F25: { | H25: "zahlbarDurch":" | I25: BKW Energie AG | J25: ","pensumm":" | K25: 100 | L25: ","betrag":" | M25: 1000 | N25: ","gueltigVon":" | O25: ="01.01."&YEAR(TODAY()) -> 01.01.2025 | P25: ","gueltigBis":" | Q25: ="31.12."&YEAR(TODAY()) -> 31.12.2025 | R25: ","checkbox":" | S25: x | T25: "} | AI25: 10643 | AL25: 11047 | AM25: =AL25/($AI25) -> 1.0379592 | AN25: 11734 | AO25: =AN25/($AI25) -> 1.1025087 | AP25: 12167 | AQ25: =AP25/($AI25) -> 1.1431927 | AR25: 11254 | AS25: =AR25/($AI25) -> 1.0574086 | AT25: 11496 | AU25: =AT25/($AI25) -> 1.0801466 | AV25: 11443 | AW25: =AV25/($AI25) -> 1.0751668 | AX25: 11104 | AY25: =AX25/($AI25) -> 1.0433149 | AZ25: 4691 | BB25: 4695 | BC25: =BB25/($AI25) -> 0.44113502 | BD25: 4689 | BE25: =BD25/($AI25) -> 0.44057127 | BF25: 4733 | BG25: =BF25/($AI25) -> 0.44470544 | BH25: 4865 | BI25: =BH25/($AI25) -> 0.45710796 | BK25: 4977 | BL25: =BK25/($AI25) -> 0.46763131 | BM25: 5121 | BN25: =BM25/($AI25) -> 0.48116133 | BO25: 5076 | BP25: =BO25/($AI25) -> 0.4769332 | BQ25: 4962 | BR25: =BQ25/($AI25) -> 0.46622193 | BS25: 5164 | BT25: =BS25/($AI25) -> 0.48520154 | BU25: 5050 | BV25: =BU25/($AI25) -> 0.47449028 | BW25: 5029 | BX25: =BW25/($AI25) -> 0.47251715 | BY25: 5045 | BZ25: =BY25/($AI25) -> 0.47402048 | CA25: 5105 | CB25: =CA25/($AI25) -> 0.47965799 | CC25: 4650 | CD25: =CC25/($AI25) -> 0.43690689 | CE25: 2082 | CF25: =CE25/($AI25) -> 0.19562154 | CG25: 1950 | CH25: =CG25/($AI25) -> 0.18321902 | CI25: 1980 | CJ25: =CI25/($AI25) -> 0.18603777 | CK25: 5065 | CL25: =CK25/($AI25) -> 0.47589965 | CM25: 7022 | CN25: =CM25/($AI25) -> 0.65977638 | CO25: 5085 | CP25: =CO25/($AI25) -> 0.47777882 | CQ25: 5042 | CR25: =CQ25/($AI25) -> 0.47373861 | CS25: 7032 | CT25: =CS25/($AI25) -> 0.66071596 | CU25: 4971 | CV25: =CU25/($AI25) -> 0.46706756 | CW25: 4855 | CX25: =CW25/($AI25) -> 0.45616837 | CY25: 5595
