Workbook
Name SpeedFaktor: '000'!$E$16

Sheet 000
A1: StepNumber | B1: Action | C1: TestData | D1: Screenshot | F1: video | G1: =5*60*1000*SpeedFaktor -> 300000 | H1: 500 | S1: Testresult | T1: 09.12.2024 10:35:06 | U1: 09.12.2024 11:14:33 | V1: Run Time Step (ms) 26.06.2025 23:17:01 | W1: Hoch | X1: Run Time Step (ms) 27.06.2025 10:30:47 | Y1: Hoch | Z1: Run Time Step (ms) 30.06.2025 14:38:55 | AA1: Hoch | AB1: Run Time Step (ms) 30.06.2025 19:22:09 | AC1: Hoch | AD1: Run Time Step (ms) 30.06.2025 20:14:13 | AE1: Hoch | AF1: Run Time Step (ms) 04.07.2025 23:23:59 | AG1: Hoch | AH1: 07.08.2025 19:32:03 | AI1: Message | AJ1: 07.08.2025 19:34:23 | AK1: Message | AL1: 07.08.2025 20:58:26 | AM1: Message | AN1: 07.08.2025 21:27:48 | AO1: Message | AP1: 08.08.2025 08:12:28 | AQ1: Message | AR1: 08.08.2025 08:21:51 | AS1: Message | AT1: 08.08.2025 08:53:08 | AU1: Message | AV1: 08.08.2025 08:54:16 | AW1: Message | AX1: 08.08.2025 09:01:35 | AY1: Message | AZ1: 08.08.2025 10:01:53 | BA1: Message | BB1: 08.08.2025 10:15:35 | BC1: Message | BD1: 08.08.2025 10:41:56 | BE1: Message | BF1: 08.08.2025 10:51:24 | BG1: Message | BH1: 08.08.2025 11:00:00 | BI1: Message | BJ1: 19.08.2025 08:51:10 | BK1: Message | BL1: 27.08.2025 20:22:29 | BM1: Message | BN1: 27.08.2025 22:18:08 | BO1: Message | BP1: 28.08.2025 07:17:13 | BQ1: Message | BR1: 28.08.2025 07:22:34 | BS1: Message
A2: 1 | B2: L00_URLAventis | C2: {"url":p.aventisURL} | T2: 3063 | U2: 1257 | V2: 955 | W2: =V2/$T2 -> 0.31178583 | X2: 869 | Y2: =X2/$T2 -> 0.28370878 | Z2: 1139 | AA2: =Z2/$T2 -> 0.37185766 | AB2: 1036 | AC2: =AB2/$T2 -> 0.33823049 | AD2: 1365 | AE2: =AD2/$AD2 -> 1 | AF2: 578 | AG2: =AF2/$T2 -> 0.18870389 | AH2: 1536 | AJ2: 1579 | AL2: 1694 | AN2: 1577 | AP2: 1530 | AR2: 1597 | AT2: 1577 | AV2: 1537 | AX2: 1741 | AZ2: 1556 | BB2: 1556 | BD2: 1584 | BF2: 1619 | BH2: 1570 | BJ2: 1517 | BL2: 924 | BN2: 948 | BP2: 895 | BR2: 1212
A3: 3 | B3: M01_LoginMSOnline | C3: {"username":"aventis-test-aml@diartis.ch","password":"E7Qr=3cTiz$8Q!","fullname":"Test AmtsleiterIn Aventis","team":"Superuser"} | T3: 7444 | U3: 8520 | V3: 4134 | W3: =V3/$T3 -> 0.55534659 | X3: 4061 | Y3: =X3/$T3 -> 0.54554003 | Z3: 9115 | AA3: =Z3/$T3 -> 1.2244761 | AB3: 14909 | AC3: =AB3/$T3 -> 2.0028211 | AD3: 13083 | AE3: =AD3/$AD3 -> 1 | AF3: 3579 | AG3: =AF3/$T3 -> 0.4807899 | AH3: 5988 | AJ3: 5325 | AL3: 7119 | AN3: 6887 | AP3: 6478 | AR3: 5652 | AT3: 6187 | AV3: 7178 | AX3: 6887 | AZ3: 5810 | BB3: 7446 | BD3: 6682 | BF3: 5985 | BH3: 5513 | BJ3: 5105 | BL3: 6005 | BN3: 7947 | BP3: 5962 | BR3: 7666
A4: 4 | B4: L05_Check_VersionNumber | C4: =E4 -> {"username":"Bern.Sachbearbeiterin@diartis.ch","password":"XXxa22?pdTA66-S@","url":p.AventisURL,"version":"2025.4.244-dev"} | D4: yes | E4: =F4&G4&H4&I4&J4&K4&L4&M4&N4&O4&P4 -> {"username":"Bern.Sachbearbeiterin@diartis.ch","password":"XXxa22?pdTA66-S@","url":p.AventisURL,"version":"2025.4.244-dev"} | F4: {"username":" | G4: Bern.Sachbearbeiterin@diartis.ch | H4: ","password":" | I4: XXxa22?pdTA66-S@ | J4: ","url": | K4: p.AventisURL | L4: ,"version":" | M4: 2025.4.244-dev | N4: "} | R4: seriell | T4: 447 | U4: 0 | V4: 891 | W4: =V4/$T4 -> 1.9932886 | X4: 793 | Y4: =X4/$T4 -> 1.7740492 | Z4: 1069 | AA4: =Z4/$T4 -> 2.3914989 | AB4: 710 | AC4: =AB4/$T4 -> 1.5883669 | AD4: 1479 | AE4: =AD4/$AD4 -> 1 | AF4: 0 | AG4: =AF4/$T4 -> 0 | AH4: 752 | AJ4: 0 | AK4: TypeError: Cannot destructure property 'version' of 'undefined' as it is undefined. Screenshots: C:\Aventis\Aventis_Playwright-\test-results\videos\007_KeyWords_Smoketest-000-000-Microsoft-Edge\test-failed-1.png Videos: C:\Aventis\Aventis_Playwright-\test-results\videos\007_KeyWords_Smoketest-000-000-Microsoft-Edge\video.webm | AL4: 883 | AN4: 786 | AP4: 836 | AR4: 860 | AT4: 713 | AV4: 0 | AW4: TypeError: Cannot destructure property 'version' of 'undefined' as it is undefined. Screenshots: C:\Aventis\Aventis_Playwright-\test-results\videos\007_KeyWords_Smoketest-000-000-Microsoft-Edge\test-failed-1.png Videos: C:\Aventis\Aventis_Playwright-\test-results\videos\007_KeyWords_Smoketest-000-000-Microsoft-Edge\video.webm | AX4: 679 | AZ4: 471 | BB4: 457 | BD4: 673 | BF4: 2154 | BH4: 673 | BJ4: 0 | BK4: Error: [31mTimed out 10000ms waiting for [39m[2mexpect([22m[31mlocator[39m[2m).[22mtoHaveText[2m([22m[32mexpected[39m[2m)[22mLocator: locator('div.versions-container.ng-star-inserted').locator('span.version-row')Expected string: [32m"2025.4.[7m141[27m-dev"[39mReceived string: [31m"2025.4.[7m244[27m-dev"[39mCall log:[2m - Expect "soft toHaveText" with timeout 10000ms[22m[2m - waiting for locator('div.versions-container.ng-star-inserted').locator('span.version-row')[22m[2m 11 × locator resolved to <span class="version-row" _ngcontent-ng-c3803718529="">2025.4.244-dev</span>[22m[2m - unexpected value "2025.4.244-dev"[22m Screenshots: C:\Aventis\Aventis_Playwright-\test-results\videos\007_KeyWords_Smoketest-000-000-Microsoft-Edge\test-failed-1.png Videos: C:\Aventis\Aventis_Playwright-\test-results\videos\007_KeyWords_Smoketest-000-000-Microsoft-Edge\video.webm | BL4: 513 | BN4: 353 | BP4: 0 | BQ4: TypeError: Cannot destructure property 'version' of 'undefined' as it is undefined. Screenshots: C:\Aventis\Aventis_Playwright-\test-results\videos\007_KeyWords_Smoketest-000-000-Microsoft-Edge\test-failed-1.png Videos: C:\Aventis\Aventis_Playwright-\test-results\videos\007_KeyWords_Smoketest-000-000-Microsoft-Edge\video.webm | BR4: 0 | BS4: TypeError: Cannot destructure property 'version' of 'undefined' as it is undefined. Screenshots: C:\Aventis\Aventis_Playwright-\test-results\videos\007_KeyWords_Smoketest-000-000-Microsoft-Edge\test-failed-1.png Videos: C:\Aventis\Aventis_Playwright-\test-results\videos\007_KeyWords_Smoketest-000-000-Microsoft-Edge\video.webm
D16: SpeedFaktor | E16: 1

Sheet 02-E2E
A1: StepNumber | B1: Action | C1: TestData | D1: Screenshot | E1: done | F1: video | G1: =5*60*1000*SpeedFaktor -> 300000 | H1: 10 | AG1: Testresult | AH1: (ms) 26.06.2025 20:17:23 | AI1: Message 26.06.2025 20:17:23 | AJ1: (ms) 26.06.2025 23:17:01 | AK1: Hoch | AL1: (ms) 27.06.2025 10:30:47 | AM1: Message 27.06.2025 10:30:47 | AN1: (ms) 30.06.2025 14:38:55 | AO1: Message 30.06.2025 14:38:55 | AP1: (ms) 30.06.2025 19:22:09 | AQ1: Hoch | AR1: (ms) 30.06.2025 20:14:13 | AS1: Hoch | AT1: (ms) 04.07.2025 23:23:59 | AU1: Hoch | AV1: 21.07.2025 20:10:18 | AW1: Hoch | AX1: 21.07.2025 23:53:59
A2: 1 | B2: L00_URLAventis | C2: {"url":p.aventisURL} | E2: =F2&G2&H2&I2&J2&K2&L2&M2&N2&O2&P2&Q2&R2&S2&T2&U2&V2&W2&X2 -> {"url":"https://dev.aventis.swiss"} | F2: {"url":" | G2: https://dev.aventis.swiss | H2: "} | AH2: 268 | AJ2: 337 | AK2: =AJ2/$AH2 -> 1.2574627 | AL2: 271 | AN2: 513 | AP2: 508 | AQ2: =AP2/$AH2 -> 1.8955224 | AR2: 1200 | AS2: =AR2/$AH2 -> 4.4776119 | AT2: 632 | AU2: =AT2/$AH2 -> 2.358209 | AV2: 293 | AW2: =AV2/$AH2 -> 1.0932836 | AX2: 259
A3: 2 | B3: E01_Delay | C3: {"Pause":"3000"} | E3: =F3&G3&H3&I3&J3&K3&L3&M3&N3&O3&P3&Q3&R3&S3&T3&U3&V3&W3&X3 -> {"url":"https://dev.aventis.swiss"} | F3: {"url":" | G3: https://dev.aventis.swiss | H3: "} | AH3: 1028 | AJ3: 1091 | AK3: =AJ3/$AH3 -> 1.061284 | AL3: 1001 | AN3: 1085 | AP3: 1404 | AQ3: =AP3/$AH3 -> 1.3657588 | AR3: 1120 | AS3: =AR3/$AH3 -> 1.0894942 | AT3: 569 | AU3: =AT3/$AH3 -> 0.55350195 | AV3: 1121 | AW3: =AV3/$AH3 -> 1.0904669 | AX3: 1006
A4: 2 | B4: M01_LoginMSOnline | C4: =E4 -> {"username":"bern.sozialarbeiterin1a@diartis.ch","password":"SMze97-jkSJ59!F.","fullname":"Sozialarbeiterin 1A Bern","team":"Sozialarbeit Bern 1"} | E4: =F4&G4&H4&I4&J4&K4&L4&M4&N4&O4&P4&Q4&R4&S4&T4&U4&V4&W4&X4 -> {"username":"bern.sozialarbeiterin1a@diartis.ch","password":"SMze97-jkSJ59!F.","fullname":"Sozialarbeiterin 1A Bern","team":"Sozialarbeit Bern 1"} | F4: {"username":" | G4: bern.sozialarbeiterin1a@diartis.ch | H4: ","password":" | I4: SMze97-jkSJ59!F. | J4: ","fullname":" | K4: Sozialarbeiterin 1A Bern | L4: ","team":" | M4: Sozialarbeit Bern 1 | N4: "} | AH4: 3012 | AJ4: 3014 | AK4: =AJ4/$AH4 -> 1.000664 | AL4: 3004 | AN4: 3033 | AP4: 3021 | AQ4: =AP4/$AH4 -> 1.002988 | AR4: 3046 | AS4: =AR4/$AH4 -> 1.0112882 | AT4: 3010 | AU4: =AT4/$AH4 -> 0.99933599 | AV4: 3008 | AW4: =AV4/$AH4 -> 0.99867198 | AX4: 3018
A5: 3 | B5: P01_Person_Search | C5: =E5 -> {"name":p.FamilyName2,"vorname":p.ManFirstName2,"ahvNumber":"","geburtsdatum":""} | E5: =F5&G5&H5&I5&J5&K5&L5&M5&N5&O5&P5&Q5&R5&S5&T5&U5&V5&W5&X5 -> {"name":p.FamilyName2,"vorname":p.ManFirstName2,"ahvNumber":"","geburtsdatum":""} | F5: {"name": | G5: =G45 -> p.FamilyName2 | H5: ,"vorname": | I5: =H$44 -> p.ManFirstName2 | J5: ,"ahvNumber":"" | L5: ,"geburtsdatum":" | N5: "} | Y5: B - Aufenthalterin / Aufenthalter | AH5: 4526 | AJ5: 4447 | AK5: =AJ5/$AH5 -> 0.98254529 | AL5: 5688 | AN5: 11496 | AP5: 11052 | AQ5: =AP5/$AH5 -> 2.4418913 | AR5: 17524 | AS5: =AR5/$AH5 -> 3.8718515 | AT5: 3672 | AU5: =AT5/$AH5 -> 0.81131242 | AV5: 4852 | AW5: =AV5/$AH5 -> 1.0720283 | AX5: 4692
A6: 4 | B6: P05_Person_Create_Manual_Complete | C6: =E6 -> {"name":p.FamilyName2,"vorname":p.ManFirstName2,"ahvNumber":p.AHVNumber5,"language":"Deutsch","zivilstand":"ledig","zivilStandSeit":"28.07.2025","geburtsdatum":"4.5.1962","national":"Frankreich","gender":"männlich","aufenthalt":"","aufGultigVon":"03.10.2025","aufGueltigBis":"13.02.2026"} | E6: =F6&G6&H6&I6&J6&K6&L6&M6&N6&O6&P6&Q6&R6&S6&T6&U6&V6&W6&X6&Y6&Z6&AA6&AB6&AC6&AD6&AE6 -> {"name":p.FamilyName2,"vorname":p.ManFirstName2,"ahvNumber":p.AHVNumber5,"language":"Deutsch","zivilstand":"ledig","zivilStandSeit":"28.07.2025","geburtsdatum":"4.5.1962","national":"Frankreich","gender":"männlich","aufenthalt":"","aufGultigVon":"03.10.2025","aufGueltigBis":"13.02.2026"} | F6: {"name": | G6: =G5 -> p.FamilyName2 | H6: ,"vorname": | I6: =H$44 -> p.ManFirstName2 | J6: ,"ahvNumber": | K6: =I44 -> p.AHVNumber5 | L6: ,"language":" | M6: Deutsch | N6: ","zivilstand":" | O6: ledig | P6: ","zivilStandSeit":" | Q6: =TEXT(TEXT(TODAY()-100,"DD")&"."&TEXT(TODAY()-100,"MM")&"."&TEXT(TODAY()-100,"YYYY"),"DD.MM.YYYY") -> 28.07.2025 | R6: ","geburtsdatum":" | S6: =TEXT(RANDBETWEEN(1,28)&"."&RANDBETWEEN(1,12)&"."&TEXT(TODAY()-23115,"YYYY"),"DD.MM.YYYY") -> 4.5.1962 | T6: ","national":" | U6: Frankreich | V6: ","gender":" | W6: männlich | X6: ","aufenthalt":" | Z6: ","aufGultigVon":" | AA6: =TEXT(TEXT(TODAY()-33,"DD")&"."&TEXT(TODAY()-33,"MM")&"."&TEXT(TODAY()-33,"YYYY"),"DD.MM.YYYY") -> 03.10.2025 | AB6: ","aufGueltigBis":" | AC6: =TEXT(TEXT(TODAY()+100,"DD")&"."&TEXT(TODAY()+100,"MM")&"."&TEXT(TODAY()+100,"YYYY"),"DD.MM.YYYY") -> 13.02.2026 | AD6: "} | AH6: 2086 | AJ6: 1871 | AK6: =AJ6/$AH6 -> 0.89693193 | AL6: 1804 | AN6: 4532 | AP6: 4671 | AQ6: =AP6/$AH6 -> 2.2392138 | AR6: 4104 | AS6: =AR6/$AH6 -> 1.9674017 | AT6: 1293 | AU6: =AT6/$AH6 -> 0.6198466 | AV6: 2003 | AW6: =AV6/$AH6 -> 0.96021093 | AX6: 2059
A7: 5 | B7: P10_Person_Communikation_Complete | C7: =E7 -> {"mobile":"079 5571045","privateNumber":"079 5480880","email":"6684abc@gmail.com"} | E7: =F7&G7&H7&I7&J7&K7&L7&M7&N7&O7&P7&Q7&R7&S7&T7&U7&V7&W7&X7 -> {"mobile":"079 5571045","privateNumber":"079 5480880","email":"6684abc@gmail.com"} | F7: {"mobile":" | G7: ="079 "&RANDBETWEEN(5234500,5699999) -> 079 5571045 | H7: ","privateNumber":" | I7: ="079 "&RANDBETWEEN(5234500,5699999) -> 079 5480880 | J7: ","email":" | K7: =RANDBETWEEN(1111,9999)&"abc@gmail.com" -> 6684abc@gmail.com | L7: "} | AH7: 3047 | AJ7: 2990 | AK7: =AJ7/$AH7 -> 0.98129308 | AL7: 2746 | AN7: 4852 | AP7: 5139 | AQ7: =AP7/$AH7 -> 1.686577 | AR7: 5398 | AS7: =AR7/$AH7 -> 1.7715786 | AT7: 2266 | AU7: =AT7/$AH7 -> 0.74368231 | AV7: 3094 | AW7: =AV7/$AH7 -> 1.015425 | AX7: 3218
A8: 6 | B8: P15_Person_Adress | C8: =E8 -> {"zusatz":"","strasse":"Strasse_792","houseNumber":"13","ort":"3053 Münchenbuchsee","validDate":"22.12.2021"} | E8: =F8&G8&H8&I8&J8&K8&L8&M8&N8&O8&P8&Q8&R8&S8&T8&U8&V8&W8&X8 -> {"zusatz":"","strasse":"Strasse_792","houseNumber":"13","ort":"3053 Münchenbuchsee","validDate":"22.12.2021"} | F8: {"zusatz":" | H8: ","strasse":" | I8: ="Strasse_"&RANDBETWEEN(1,1000) -> Strasse_792 | J8: ","houseNumber":" | K8: =RANDBETWEEN(1,100) -> 13 | L8: ","ort":" | M8: 3053 Münchenbuchsee | N8: ","validDate":" | O8: =TEXT(RANDBETWEEN(1,28)&"."&RANDBETWEEN(1,12)&"."&TEXT(TODAY()-4*365,"YYYY"),"DD.MM.YYYY") -> 22.12.2021 | P8: "} | AH8: 378 | AJ8: 234 | AK8: =AJ8/$AH8 -> 0.61904762 | AL8: 276 | AN8: 846 | AP8: 770 | AQ8: =AP8/$AH8 -> 2.037037 | AR8: 1011 | AS8: =AR8/$AH8 -> 2.6746032 | AT8: 284 | AU8: =AT8/$AH8 -> 0.75132275 | AV8: 304 | AW8: =AV8/$AH8 -> 0.8042328 | AX8: 324
A9: 7 | B9: P20_Person_ZahlungsVerbindung | C9: {"iban":"CH21 0078 9100 0000 2920 0"} | AH9: 4861 | AJ9: 4692 | AK9: =AJ9/$AH9 -> 0.96523349 | AL9: 4723 | AN9: 5140 | AP9: 6034 | AQ9: =AP9/$AH9 -> 1.2413084 | AR9: 5993 | AS9: =AR9/$AH9 -> 1.2328739 | AT9: 4678 | AU9: =AT9/$AH9 -> 0.96235343 | AV9: 5041 | AW9: =AV9/$AH9 -> 1.0370294 | AX9: 4960
A10: 8 | B10: P30_Person_Uebernehmen | AH10: 81 | AJ10: 94 | AK10: =AJ10/$AH10 -> 1.1604938 | AL10: 95 | AN10: 588 | AP10: 569 | AQ10: =AP10/$AH10 -> 7.0246914 | AR10: 321 | AS10: =AR10/$AH10 -> 3.962963 | AT10: 129 | AU10: =AT10/$AH10 -> 1.5925926 | AV10: 86 | AW10: =AV10/$AH10 -> 1.0617284 | AX10: 105
A11: 9 | B11: H01_Haushalt_Uebernehmen_Zustaendigkeit | C11: =E11 -> {"zust_Gemeinde":"Münchenbuchsee","zust_SozTeam":"Sozialarbeit Bern 1","zust_SozMitarbeiter":"Bern Sozialarbeiterin 1A","zust_SachbTeam":"Sachbearbeitung Bern","zust_SachbMitarbeiter":"Bern Sachbearbeiterin"} | E11: =F11&G11&H11&I11&J11&K11&L11&M11&N11&O11&P11&Q11&R11&S11&T11&U11&V11&W11&X11 -> {"zust_Gemeinde":"Münchenbuchsee","zust_SozTeam":"Sozialarbeit Bern 1","zust_SozMitarbeiter":"Bern Sozialarbeiterin 1A","zust_SachbTeam":"Sachbearbeitung Bern","zust_SachbMitarbeiter":"Bern Sachbearbeiterin"} | F11: {"zust_Gemeinde":" | G11: Münchenbuchsee | H11: ","zust_SozTeam":" | I11: Sozialarbeit Bern 1 | J11: ","zust_SozMitarbeiter":" | K11: Bern Sozialarbeiterin 1A | L11: ","zust_SachbTeam":" | M11: Sachbearbeitung Bern | N11: ","zust_SachbMitarbeiter":" | O11: Bern Sachbearbeiterin | P11: "} | AH11: 1159 | AJ11: 1171 | AK11: =AJ11/$AH11 -> 1.0103538 | AL11: 1205 | AN11: 1426 | AP11: 1553 | AQ11: =AP11/$AH11 -> 1.3399482 | AR11: 1799 | AS11: =AR11/$AH11 -> 1.5522002 | AT11: 1229 | AU11: =AT11/$AH11 -> 1.0603969 | AV11: 1204 | AW11: =AV11/$AH11 -> 1.0388266 | AX11: 1221
A12: 10 | B12: D01_Dossier_Eroeffnen | C12: =E12 -> {"dossierBezeichnung":p.DossierName2,"eroeffnetAm":"05.11.2025","dossierSprache":"Deutsch"} | D12: yes | E12: =F12&G12&H12&I12&J12&K12&L12&M12&N12&O12&P12&Q12&R12&S12&T12&U12&V12&W12&X12 -> {"dossierBezeichnung":p.DossierName2,"eroeffnetAm":"05.11.2025","dossierSprache":"Deutsch"} | F12: {"dossierBezeichnung": | G12: =G44 -> p.DossierName2 | H12: ,"eroeffnetAm":" | I12: =TEXT(TEXT(TODAY(),"DD")&"."&TEXT(TODAY(),"MM")&"."&TEXT(TODAY(),"YYYY"),"DD.MM.YYYY") -> 05.11.2025 | J12: ","dossierSprache":" | K12: Deutsch | L12: "} | AH12: 4199 | AJ12: 4049 | AK12: =AJ12/$AH12 -> 0.96427721 | AL12: 4080 | AN12: 4423 | AP12: 4546 | AQ12: =AP12/$AH12 -> 1.0826387 | AR12: 4547 | AS12: =AR12/$AH12 -> 1.0828769 | AT12: 3596 | AU12: =AT12/$AH12 -> 0.85639438 | AV12: 4073 | AW12: =AV12/$AH12 -> 0.96999286 | AX12: 4404
A13: 11 | B13: BW04_ZahlungsVerbindung_Freigeben | C13: =E13 -> {"dossierInstitution":p.DossierName2,"klientschaft":`${p.FamilyName2}, ${p.ManFirstName2}`,"buttonBewilligung":"Anfragen","checkStatus":"In Bearbeitung"} | E13: =F13&G13&H13&I13&J13&K13&L13&M13&N13&O13&P13&Q13&R13&S13&T13&U13&V13&W13&X13 -> {"dossierInstitution":p.DossierName2,"klientschaft":`${p.FamilyName2}, ${p.ManFirstName2}`,"buttonBewilligung":"Anfragen","checkStatus":"In Bearbeitung"} | F13: {"dossierInstitution": | G13: =G12 -> p.DossierName2 | H13: ,"klientschaft":` | I13: =I23 -> ${p.FamilyName2}, ${p.ManFirstName2} | J13: `,"buttonBewilligung":" | K13: Anfragen | L13: ","checkStatus":" | M13: In Bearbeitung | N13: "} | AH13: 1522 | AJ13: 1540 | AK13: =AJ13/$AH13 -> 1.0118265 | AL13: 1480 | AN13: 1388 | AP13: 1517 | AQ13: =AP13/$AH13 -> 0.99671485 | AR13: 1581 | AS13: =AR13/$AH13 -> 1.0387648 | AT13: 1114 | AU13: =AT13/$AH13 -> 0.73193167 | AV13: 938 | AW13: =AV13/$AH13 -> 0.61629435 | AX13: 962
A14: 12 | B14: L03_LogoutAndLoginDiffAccount | C14: =E14 -> {"username":"Bern.Sachbearbeiterin@diartis.ch","password":"XXxa22?pdTA66-S@"} | E14: =F14&G14&H14&I14&J14&K14&L14&M14&N14&O14&P14&Q14&R14&S14&T14&U14&V14&W14&X14 -> {"username":"Bern.Sachbearbeiterin@diartis.ch","password":"XXxa22?pdTA66-S@"} | F14: {"username":" | G14: Bern.Sachbearbeiterin@diartis.ch | H14: ","password":" | I14: XXxa22?pdTA66-S@ | J14: "} | AH14: 10701 | AJ14: 10596 | AK14: =AJ14/$AH14 -> 0.99018783 | AL14: 10449 | AN14: 15172 | AP14: 13669 | AQ14: =AP14/$AH14 -> 1.2773573 | AR14: 15047 | AS14: =AR14/$AH14 -> 1.4061303 | AT14: 9450 | AU14: =AT14/$AH14 -> 0.88309504 | AV14: 10572 | AW14: =AV14/$AH14 -> 0.98794505 | AX14: 10072
A15: 13 | B15: BW04_ZahlungsVerbindung_Freigeben | C15: =E15 -> {"dossierInstitution":p.DossierName2,"klientschaft":`${p.FamilyName2}, ${p.ManFirstName2}`,"buttonBewilligung":"Bewilligen","checkStatus":"Bewilligt"} | E15: =F15&G15&H15&I15&J15&K15&L15&M15&N15&O15&P15&Q15&R15&S15&T15&U15&V15&W15&X15 -> {"dossierInstitution":p.DossierName2,"klientschaft":`${p.FamilyName2}, ${p.ManFirstName2}`,"buttonBewilligung":"Bewilligen","checkStatus":"Bewilligt"} | F15: {"dossierInstitution": | G15: =G13 -> p.DossierName2 | H15: ,"klientschaft":` | I15: =I23 -> ${p.FamilyName2}, ${p.ManFirstName2} | J15: `,"buttonBewilligung":" | K15: Bewilligen | L15: ","checkStatus":" | M15: Bewilligt | N15: "} | AH15: 10109 | AJ15: 9610 | AK15: =AJ15/$AH15 -> 0.95063805 | AL15: 9677 | AN15: 19957 | AP15: 17559 | AQ15: =AP15/$AH15 -> 1.7369671 | AR15: 16816 | AS15: =AR15/$AH15 -> 1.6634682 | AT15: 9433 | AU15: =AT15/$AH15 -> 0.9331289 | AV15: 9995 | AW15: =AV15/$AH15 -> 0.98872292 | AX15: 10100
A16: 14 | B16: L03_LogoutAndLoginDiffAccount | C16: {"username":"bern.sozialarbeiterin1a@diartis.ch","password":"SMze97-jkSJ59!F."} | E16: 2 | F16: {"username":" | G16: Bern.Sachbearbeiterin@diartis.ch | H16: ","password":" | I16: XXxa22?pdTA66-S@ | J16: "} | AH16: 9903 | AJ16: 10024 | AK16: =AJ16/$AH16 -> 1.0122185 | AL16: 10034 | AN16: 15378 | AP16: 23525 | AQ16: =AP16/$AH16 -> 2.3755428 | AR16: 15204 | AS16: =AR16/$AH16 -> 1.5352923 | AT16: 10291 | AU16: =AT16/$AH16 -> 1.03918 | AV16: 10804 | AW16: =AV16/$AH16 -> 1.0909825 | AX16: 10496
A17: 16 | B17: DO11_Dossier_Search_Lupe | C17: =E17 -> {"searchDossierOrKlient":p.DossierName2,"resultType":"Dossiers"} | E17: =F17&G17&H17&I17&J17&K17&L17&M17&N17&O17&P17&Q17&R17&S17&T17&U17&V17&W17&X17 -> {"searchDossierOrKlient":p.DossierName2,"resultType":"Dossiers"} | F17: {"searchDossierOrKlient": | G17: =G15 -> p.DossierName2 | H17: ,"resultType":" | I17: Dossiers | J17: "} | AH17: 9652 | AJ17: 9517 | AK17: =AJ17/$AH17 -> 0.98601326 | AL17: 9448 | AN17: 13207 | AP17: 16203 | AQ17: =AP17/$AH17 -> 1.6787194 | AR17: 39846 | AS17: =AR17/$AH17 -> 4.1282636 | AT17: 9655 | AU17: =AT17/$AH17 -> 1.0003108 | AV17: 10327 | AW17: =AV17/$AH17 -> 1.0699337 | AX17: 9292
A18: 18 | B18: WO32_01b_Wohnsituation_Haushalt_Wohnung_anpassen | C18: =E18 -> {"vermieter":"Graber Immobilien","wohnungsgrosse":"4 Zimmer","mietkosten":1200,"nebenkosten":100} | E18: =F18&G18&H18&I18&J18&K18&L18&M18&N18&O18&P18&Q18&R18&S18&T18&U18&V18&W18&X18 -> {"vermieter":"Graber Immobilien","wohnungsgrosse":"4 Zimmer","mietkosten":1200,"nebenkosten":100} | F18: {"vermieter":" | G18: Graber Immobilien | H18: ","wohnungsgrosse":" | I18: 4 Zimmer | J18: ","mietkosten": | K18: 1200 | L18: ,"nebenkosten": | M18: 100 | N18: } | AH18: 5632 | AJ18: 5705 | AK18: =AJ18/$AH18 -> 1.0129616 | AL18: 5734 | AN18: 8754 | AP18: 9511 | AQ18: =AP18/$AH18 -> 1.6887429 | AR18: 41783 | AS18: =AR18/$AH18 -> 7.4188565 | AT18: 6286 | AU18: =AT18/$AH18 -> 1.1161222 | AV18: 6299 | AW18: =AV18/$AH18 -> 1.1184304 | AX18: 6081
A19: 19 | B19: WO30_Wohnsituation_Haushalt_Person_Hinzufuegen | C19: =E19 -> {"name":p.FamilyName2,"vorname":p.ManFirstName3,"geburtsdatum":p.BirthdayKid3,"ahvNumber":p.AHVNumber8,"personInhausltVon":"05.11.2025","inHauslt":"Übernehmen","ereignis":"Eheschliessung"} | E19: =F19&G19&H19&I19&J19&K19&L19&M19&N19&O19&P19&Q19&R19&S19&T19&U19&V19&W19&X19 -> {"name":p.FamilyName2,"vorname":p.ManFirstName3,"geburtsdatum":p.BirthdayKid3,"ahvNumber":p.AHVNumber8,"personInhausltVon":"05.11.2025","inHauslt":"Übernehmen","ereignis":"Eheschliessung"} | F19: {"name": | G19: =G6 -> p.FamilyName2 | H19: ,"vorname": | I19: =H47 -> p.ManFirstName3 | J19: ,"geburtsdatum": | K19: =J47 -> p.BirthdayKid3 | L19: ,"ahvNumber": | M19: =I47 -> p.AHVNumber8 | N19: ,"personInhausltVon":" | O19: =I12 -> 05.11.2025 | P19: ","inHauslt":" | Q19: Übernehmen | R19: ","ereignis":" | S19: Eheschliessung | T19: "} | AH19: 3543 | AJ19: 3481 | AK19: =AJ19/$AH19 -> 0.98250071 | AL19: 3559 | AN19: 7101 | AP19: 7334 | AQ19: =AP19/$AH19 -> 2.0699972 | AR19: 7519 | AS19: =AR19/$AH19 -> 2.1222128 | AT19: 3519 | AU19: =AT19/$AH19 -> 0.99322608 | AV19: 3931 | AW19: =AV19/$AH19 -> 1.1095117 | AX19: 3929
A20: 20 | B20: WO30_Wohnsituation_Haushalt_Person_Hinzufuegen | C20: =E20 -> {"name":p.FamilyName2,"vorname":p.WomanFirstName2,"geburtsdatum":p.BirthdayAdult3,"ahvNumber":p.AHVNumber6,"personInhausltVon":"05.11.2025","inHauslt":"Übernehmen","ereignis":"Geburt"} | E20: =F20&G20&H20&I20&J20&K20&L20&M20&N20&O20&P20&Q20&R20&S20&T20&U20&V20&W20&X20 -> {"name":p.FamilyName2,"vorname":p.WomanFirstName2,"geburtsdatum":p.BirthdayAdult3,"ahvNumber":p.AHVNumber6,"personInhausltVon":"05.11.2025","inHauslt":"Übernehmen","ereignis":"Geburt"} | F20: {"name": | G20: =G19 -> p.FamilyName2 | H20: ,"vorname": | I20: =H45 -> p.WomanFirstName2 | J20: ,"geburtsdatum": | K20: =J45 -> p.BirthdayAdult3 | L20: ,"ahvNumber": | M20: =I45 -> p.AHVNumber6 | N20: ,"personInhausltVon":" | O20: =O19 -> 05.11.2025 | P20: ","inHauslt":" | Q20: Übernehmen | R20: ","ereignis":" | S20: Geburt | T20: "} | AH20: 2324 | AJ20: 2582 | AK20: =AJ20/$AH20 -> 1.1110155 | AL20: 2223 | AN20: 5141 | AP20: 5203 | AQ20: =AP20/$AH20 -> 2.2388124 | AR20: 5669 | AS20: =AR20/$AH20 -> 2.4393287 | AT20: 2304 | AU20: =AT20/$AH20 -> 0.99139415 | AV20: 2826 | AW20: =AV20/$AH20 -> 1.2160069 | AX20: 2630
A21: 21 | B21: WO30_Wohnsituation_Haushalt_Person_Hinzufuegen | C21: =E21 -> {"name":p.FamilyName2,"vorname":p.GirlFirstName2,"geburtsdatum":p.BirthdayKid2,"ahvNumber":p.AHVNumber7,"personInhausltVon":"05.11.2025","inHauslt":"Übernehmen","ereignis":"Geburt"} | E21: =F21&G21&H21&I21&J21&K21&L21&M21&N21&O21&P21&Q21&R21&S21&T21&U21&V21&W21&X21 -> {"name":p.FamilyName2,"vorname":p.GirlFirstName2,"geburtsdatum":p.BirthdayKid2,"ahvNumber":p.AHVNumber7,"personInhausltVon":"05.11.2025","inHauslt":"Übernehmen","ereignis":"Geburt"} | F21: {"name": | G21: =G20 -> p.FamilyName2 | H21: ,"vorname": | I21: =H46 -> p.GirlFirstName2 | J21: ,"geburtsdatum": | K21: =J46 -> p.BirthdayKid2 | L21: ,"ahvNumber": | M21: =I46 -> p.AHVNumber7 | N21: ,"personInhausltVon":" | O21: =O20 -> 05.11.2025 | P21: ","inHauslt":" | Q21: Übernehmen | R21: ","ereignis":" | S21: Geburt | T21: "} | AH21: 2702 | AJ21: 2886 | AK21: =AJ21/$AH21 -> 1.0680977 | AL21: 2683 | AN21: 5897 | AP21: 6769 | AQ21: =AP21/$AH21 -> 2.5051813 | AR21: 5964 | AS21: =AR21/$AH21 -> 2.2072539 | AT21: 2715 | AU21: =AT21/$AH21 -> 1.0048113 | AV21: 3007 | AW21: =AV21/$AH21 -> 1.1128793 | AX21: 3037
A22: 22 | B22: WO32_01b_Wohnsituation_Haushalt_Wohnung_anpassen | C22: =E22 -> {"vermieter":"Graber Immobilien","wohnungsgrosse":"4 Zimmer","mietkosten":3000,"nebenkosten":300} | E22: =F22&G22&H22&I22&J22&K22&L22&M22&N22&O22&P22&Q22&R22&S22&T22&U22&V22&W22&X22 -> {"vermieter":"Graber Immobilien","wohnungsgrosse":"4 Zimmer","mietkosten":3000,"nebenkosten":300} | F22: {"vermieter":" | G22: Graber Immobilien | H22: ","wohnungsgrosse":" | I22: 4 Zimmer | J22: ","mietkosten": | K22: 3000 | L22: ,"nebenkosten": | M22: 300 | N22: } | AH22: 2397 | AJ22: 2625 | AK22: =AJ22/$AH22 -> 1.0951189 | AL22: 2732 | AN22: 5588 | AP22: 5282 | AQ22: =AP22/$AH22 -> 2.2035878 | AR22: 6515 | AS22: =AR22/$AH22 -> 2.7179808 | AT22: 2529 | AU22: =AT22/$AH22 -> 1.0550688 | AV22: 2971 | AW22: =AV22/$AH22 -> 1.239466 | AX22: 2875
A23: 23 | B23: KL01_Klientschaft_select | C23: =E23 -> {"dossier":p.DossierName2,"klientschaft":`${p.FamilyName2}, ${p.ManFirstName2}`} | E23: =F23&G23&H23&I23&J23&K23&L23&M23&N23&O23&P23&Q23&R23&S23&T23&U23&V23&W23&X23 -> {"dossier":p.DossierName2,"klientschaft":`${p.FamilyName2}, ${p.ManFirstName2}`} | F23: {"dossier": | G23: =G12 -> p.DossierName2 | H23: ,"klientschaft":` | I23: ="${"&$G$5&"}, ${"&$I$5&"}" -> ${p.FamilyName2}, ${p.ManFirstName2} | J23: `} | AH23: 4761 | AJ23: 3094 | AK23: =AJ23/$AH23 -> 0.64986347 | AL23: 3005 | AN23: 6515 | AP23: 6425 | AQ23: =AP23/$AH23 -> 1.3495064 | AR23: 5479 | AS23: =AR23/$AH23 -> 1.1508087 | AT23: 2856 | AU23: =AT23/$AH23 -> 0.59987398 | AV23: 3298 | AW23: =AV23/$AH23 -> 0.69271162 | AX23: 3316
A24: 24 | B24: KL03_ErwerbsituationEinnahmen_Lohn_erfassen | C24: =E24 -> {"panelTitle":"Erwerbssituation / Einnahmen","zahlbarDurch":"BKW Energie AG","pensumm":"100","betrag":"1000","gueltigVon":"01.01.2024","gueltigBis":"31.12.2025","checkbox":"x"} | E24: =F24&G24&H24&I24&J24&K24&L24&M24&N24&O24&P24&Q24&R24&S24&T24&U24&V24&W24&X24 -> {"panelTitle":"Erwerbssituation / Einnahmen","zahlbarDurch":"BKW Energie AG","pensumm":"100","betrag":"1000","gueltigVon":"01.01.2024","gueltigBis":"31.12.2025","checkbox":"x"} | F24: {"panelTitle":" | G24: Erwerbssituation / Einnahmen | H24: ","zahlbarDurch":" | I24: BKW Energie AG | J24: ","pensumm":" | K24: 100 | L24: ","betrag":" | M24: 1000 | N24: ","gueltigVon":" | O24: ="01.01."&YEAR((TODAY()-366)) -> 01.01.2024 | P24: ","gueltigBis":" | Q24: ="31.12."&YEAR(TODAY()) -> 31.12.2025 | R24: ","checkbox":" | S24: x | T24: "} | AK24: =AJ24/$AH24 -> #DIV/0! | AQ24: =AP24/$AH24 -> #DIV/0! | AS24: =AR24/$AH24 -> #DIV/0! | AU24: =AT24/$AH24 -> #DIV/0! | AV24: 5303 | AW24: =AV24/$AH24 -> #DIV/0! | AX24: 5092
A25: 25 | B25: DO11_Dossier_Search_Lupe | C25: =E25 -> {"searchDossierOrKlient":p.DossierName2,"resultType":"Dossiers"} | E25: =F25&G25&H25&I25&J25&K25&L25&M25&N25&O25&P25&Q25&R25&S25&T25&U25&V25&W25&X25 -> {"searchDossierOrKlient":p.DossierName2,"resultType":"Dossiers"} | F25: {"searchDossierOrKlient": | G25: =G23 -> p.DossierName2 | H25: ,"resultType":" | I25: Dossiers | J25: "} | AH25: 4873 | AJ25: 4740 | AK25: =AJ25/$AH25 -> 0.97270675 | AL25: 4926 | AN25: 5625 | AP25: 7609 | AQ25: =AP25/$AH25 -> 1.5614611 | AR25: 6236 | AS25: =AR25/$AH25 -> 1.2797045 | AT25: 4989 | AU25: =AT25/$AH25 -> 1.0238046 | AV25: 3945 | AW25: =AV25/$AH25 -> 0.8095629 | AX25: 3975
A26: 26 | B26: KL10_Krankenversicherungen_VVG_erfassen | C26: =F26&G26&H26&I26&J26&K26&L26&M26&N26&O26 &P26&Q26&R26&S26&T26&U26&V26&W26&X26&Y26&Z26&AA26&AB26&AC26 -> {"Klientschaft":`${p.FamilyName2}, ${p.ManFirstName3}`,"Gueltigkeit":"01.01.2025 - 31.12.2025","KKasse":"Arcosana AG","VersNummer":"123","GrundPraemie":"45","ZahnInklusive":"ja","Franchise":"100","Bemerkung":"Test"} | E26: =F26&G26&H26&I26&J26&K26&L26&M26&N26&O26&P26&Q26&R26&S26&T26&U26&V26&W26&X26 -> {"Klientschaft":`${p.FamilyName2}, ${p.ManFirstName3}`,"Gueltigkeit":"01.01.2025 - 31.12.2025","KKasse":"Arcosana AG","VersNummer":"123","GrundPraemie":"45","ZahnInklusive":"ja","Franchise":"100","Bemerkung":"Test"} | F26: {"Klientschaft":` | G26: ="${"&$G$19&"}, ${"&$I$19&"}" -> ${p.FamilyName2}, ${p.ManFirstName3} | H26: `,"Gueltigkeit":" | I26: ="01.01."&YEAR(TODAY())&" - 31.12."&YEAR(TODAY()) -> 01.01.2025 - 31.12.2025 | J26: ","KKasse":" | K26: Arcosana AG | L26: ","VersNummer":" | M26: 123 | N26: ","GrundPraemie":" | O26: 45 | P26: ","ZahnInklusive":" | Q26: ja | R26: ","Franchise":" | S26: 100 | T26: ","Bemerkung":" | U26: Test | V26: "} | AK26: =AJ26/$AH26 -> #DIV/0! | AQ26: =AP26/$AH26 -> #DIV/0! | AS26: =AR26/$AH26 -> #DIV/0! | AU26: =AT26/$AH26 -> #DIV/0! | AV26: 5257 | AW26: =AV26/$AH26 -> #DIV/0! | AX26: 5229
A27: 27 | B27: A01_AnspruchPruefung_Bedarfspruefung | C27: =E27 -> {"entscheidVom":"05.11.2025","begrundung":"Gar keine Begründung","unterstutzungab":"01.11.2025"} | E27: =F27&G27&H27&I27&J27&K27&L27&M27&N27&O27&P27&Q27&R27&S27&T27&U27&V27&W27&X27 -> {"entscheidVom":"05.11.2025","begrundung":"Gar keine Begründung","unterstutzungab":"01.11.2025"} | F27: {"entscheidVom":" | G27: =TEXT(TEXT(TODAY(),"DD")&"."&TEXT(TODAY(),"MM")&"."&TEXT(TODAY(),"YYYY"),"DD.MM.YYYY") -> 05.11.2025 | H27: ","begrundung":" | I27: Gar keine Begründung | J27: ","unterstutzungab":" | K27: =TEXT(TEXT(1,"DD")&"."&TEXT(TODAY(),"MM")&"."&TEXT(TODAY(),"YYYY"),"DD.MM.YYYY") -> 01.11.2025 | L27: "} | AH27: 5177 | AJ27: 5075 | AK27: =AJ27/$AH27 -> 0.98029747 | AL27: 5226 | AN27: 5991 | AP27: 5075 | AQ27: =AP27/$AH27 -> 0.98029747 | AR27: 6129 | AS27: =AR27/$AH27 -> 1.1838903 | AT27: 4999 | AU27: =AT27/$AH27 -> 0.96561715 | AV27: 4028 | AW27: =AV27/$AH27 -> 0.77805679 | AX27: 4684
A28: 29 | B28: R01_Rahmenbudget_Wohnkosten_Anpassen_V2 | C28: =E28 -> {"ubernahmeWohnkostenCFH":"100","uebernahmeWohnkostenVon":"05.11.2025","uebernahmeWohnkostenBis":"27.5.2026","uebernahemBegruendung":"Die Wohnungen sind teuer hier"} | E28: =F28&G28&H28&I28&J28&K28&L28&M28&N28&O28&P28&Q28&R28&S28&T28&U28&V28&W28&X28 -> {"ubernahmeWohnkostenCFH":"100","uebernahmeWohnkostenVon":"05.11.2025","uebernahmeWohnkostenBis":"27.5.2026","uebernahemBegruendung":"Die Wohnungen sind teuer hier"} | F28: {"ubernahmeWohnkostenCFH":" | G28: 100 | H28: ","uebernahmeWohnkostenVon":" | I28: =TEXT(TEXT(TODAY(),"DD")&"."&TEXT(TODAY(),"MM")&"."&TEXT(TODAY(),"YYYY"),"DD.MM.YYYY") -> 05.11.2025 | J28: ","uebernahmeWohnkostenBis":" | K28: ="27."&MONTH(TODAY()+180)&"."&YEAR(TODAY()+180) -> 27.5.2026 | L28: ","uebernahemBegruendung":" | M28: Die Wohnungen sind teuer hier | N28: "} | AH28: 11210 | AJ28: 9943 | AK28: =AJ28/$AH28 -> 0.88697591 | AL28: 10600 | AN28: 20197 | AP28: 21337 | AQ28: =AP28/$AH28 -> 1.9033898 | AR28: 17788 | AS28: =AR28/$AH28 -> 1.5867975 | AT28: 8511 | AU28: =AT28/$AH28 -> 0.75923283 | AV28: 12315 | AW28: =AV28/$AH28 -> 1.0985727 | AX28: 12084
A29: 30 | B29: BW01_Bewilligungs_Workflow_LeistungsEntscheid | C29: =E29 -> {"lEvonDate":"05.11.2025","lEbisDate":"05.11.2026","checkStatus":"In Bearbeitung"} | E29: =F29&G29&H29&I29&J29&K29&L29&M29&N29&O29&P29&Q29&R29&S29&T29&U29&V29&W29&X29 -> {"lEvonDate":"05.11.2025","lEbisDate":"05.11.2026","checkStatus":"In Bearbeitung"} | F29: {"lEvonDate":" | G29: =TEXT(TEXT(TODAY(),"DD")&"."&TEXT(TODAY(),"MM")&"."&TEXT(TODAY(),"YYYY"),"DD.MM.YYYY") -> 05.11.2025 | H29: ","lEbisDate":" | I29: =TEXT(TEXT(TODAY(),"DD")&"."&TEXT(TODAY(),"MM")&"."&TEXT(TODAY()+360,"YYYY"),"DD.MM.YYYY") -> 05.11.2026 | J29: ","checkStatus":" | K29: In Bearbeitung | L29: "} | AH29: 1395 | AJ29: 1490 | AK29: =AJ29/$AH29 -> 1.0681004 | AL29: 1347 | AN29: 4456 | AP29: 4014 | AQ29: =AP29/$AH29 -> 2.8774194 | AR29: 4179 | AS29: =AR29/$AH29 -> 2.9956989 | AT29: 1088 | AU29: =AT29/$AH29 -> 0.77992832 | AV29: 2049 | AW29: =AV29/$AH29 -> 1.4688172 | AX29: 2264
B30: L03_LogoutAndLoginDiffAccount | C30: =E30 -> {"username":"aventis-gemeinde-ma@diartis.ch","password":"#xFymiADPk7wJG/FWMz"} | E30: =F30&G30&H30&I30&J30&K30&L30&M30&N30&O30&P30&Q30&R30&S30&T30&U30&V30&W30&X30 -> {"username":"aventis-gemeinde-ma@diartis.ch","password":"#xFymiADPk7wJG/FWMz"} | F30: {"username":" | G30: aventis-gemeinde-ma@diartis.ch | H30: ","password":" | I30: #xFymiADPk7wJG/FWMz | J30: "} | AH30: 10769 | AJ30: 10884 | AK30: =AJ30/$AH30 -> 1.0106788 | AL30: 10855 | AN30: 10387 | AP30: 17308 | AQ30: =AP30/$AH30 -> 1.6072059 | AR30: 15180 | AS30: =AR30/$AH30 -> 1.4096016 | AT30: 10217 | AU30: =AT30/$AH30 -> 0.94874176 | AV30: 12222 | AW30: =AV30/$AH30 -> 1.1349243 | AX30: 12394
A31: 32 | B31: L03_LogoutAndLoginDiffAccount | C31: =E31 -> {"username":"Bern.Sachbearbeiterin@diartis.ch","password":"XXxa22?pdTA66-S@"} | E31: =F31&G31&H31&I31&J31&K31&L31&M31&N31&O31&P31&Q31&R31&S31&T31&U31&V31&W31&X31 -> {"username":"Bern.Sachbearbeiterin@diartis.ch","password":"XXxa22?pdTA66-S@"} | F31: {"username":" | G31: Bern.Sachbearbeiterin@diartis.ch | H31: ","password":" | I31: XXxa22?pdTA66-S@ | J31: "} | AH31: 8652 | AJ31: 8415 | AK31: =AJ31/$AH31 -> 0.97260749 | AL31: 8627 | AN31: 12743 | AP31: 13421 | AQ31: =AP31/$AH31 -> 1.551202 | AR31: 44292 | AS31: =AR31/$AH31 -> 5.1192788 | AT31: 9257 | AU31: =AT31/$AH31 -> 1.069926 | AV31: 9452 | AW31: =AV31/$AH31 -> 1.0924642 | AX31: 8543
A32: 34 | B32: BW02b_Bewilligungs_Workflow_Step_V2 | C32: =E32 -> {"dossier":p.DossierName2,"buttonName":"Prüfung OK","checkEntscheid":"Geprüft"} | E32: =F32&G32&H32&I32&J32&K32&L32&M32&N32&O32&P32&Q32&R32&S32&T32&U32&V32&W32&X32 -> {"dossier":p.DossierName2,"buttonName":"Prüfung OK","checkEntscheid":"Geprüft"} | F32: {"dossier": | G32: =G25 -> p.DossierName2 | H32: ,"buttonName":" | I32: Prüfung OK | J32: ","checkEntscheid":" | K32: Geprüft | L32: "} | AH32: 8569 | AJ32: 8674 | AK32: =AJ32/$AH32 -> 1.0122535 | AL32: 8624 | AN32: 15490 | AP32: 15502 | AQ32: =AP32/$AH32 -> 1.8090792 | AR32: 29105 | AS32: =AR32/$AH32 -> 3.3965457 | AT32: 9568 | AU32: =AT32/$AH32 -> 1.116583 | AV32: 10373 | AW32: =AV32/$AH32 -> 1.2105263 | AX32: 11641
A33: 35 | B33: L03_LogoutAndLoginDiffAccount | C33: =E33 -> {"username":"aventis-gemeinde-ma@diartis.ch","password":"#xFymiADPk7wJG/FWMz"} | E33: =F33&G33&H33&I33&J33&K33&L33&M33&N33&O33&P33&Q33&R33&S33&T33&U33&V33&W33&X33 -> {"username":"aventis-gemeinde-ma@diartis.ch","password":"#xFymiADPk7wJG/FWMz"} | F33: {"username":" | G33: aventis-gemeinde-ma@diartis.ch | H33: ","password":" | I33: #xFymiADPk7wJG/FWMz | J33: "} | AH33: 9133 | AJ33: 9029 | AK33: =AJ33/$AH33 -> 0.98861272 | AL33: 10042 | AN33: 13106 | AP33: 15561 | AQ33: =AP33/$AH33 -> 1.7038213 | AR33: 17272 | AS33: =AR33/$AH33 -> 1.8911639 | AT33: 9475 | AU33: =AT33/$AH33 -> 1.0374466 | AV33: 10600 | AW33: =AV33/$AH33 -> 1.1606263 | AX33: 10012
A34: 37 | B34: BW02b_Bewilligungs_Workflow_Step_V2 | C34: =E34 -> {"dossier":p.DossierName2,"buttonName":"Bewilligen","checkEntscheid":""} | E34: =F34&G34&H34&I34&J34&K34&L34&M34&N34&O34&P34&Q34&R34&S34&T34&U34&V34&W34&X34 -> {"dossier":p.DossierName2,"buttonName":"Bewilligen","checkEntscheid":""} | F34: {"dossier": | G34: =G32 -> p.DossierName2 | H34: ,"buttonName":" | I34: Bewilligen | J34: ","checkEntscheid":" | L34: "} | AH34: 8024 | AJ34: 7910 | AK34: =AJ34/$AH34 -> 0.98579262 | AL34: 9136 | AN34: 12573 | AP34: 14523 | AQ34: =AP34/$AH34 -> 1.8099452 | AR34: 13839 | AS34: =AR34/$AH34 -> 1.7247009 | AT34: 8805 | AU34: =AT34/$AH34 -> 1.097333 | AV34: 10636 | AW34: =AV34/$AH34 -> 1.3255234 | AX34: 10207
A35: 38 | B35: L03_LogoutAndLoginDiffAccount | C35: =E35 -> {"username":"Bern.Sachbearbeiterin@diartis.ch","password":"XXxa22?pdTA66-S@"} | E35: =F35&G35&H35&I35&J35&K35&L35&M35&N35&O35&P35&Q35&R35&S35&T35&U35&V35&W35&X35 -> {"username":"Bern.Sachbearbeiterin@diartis.ch","password":"XXxa22?pdTA66-S@"} | F35: {"username":" | G35: Bern.Sachbearbeiterin@diartis.ch | H35: ","password":" | I35: XXxa22?pdTA66-S@ | J35: "} | AH35: 10174 | AJ35: 10415 | AK35: =AJ35/$AH35 -> 1.0236878 | AL35: 10316 | AN35: 13898 | AP35: 18727 | AQ35: =AP35/$AH35 -> 1.8406723 | AR35: 13729 | AS35: =AR35/$AH35 -> 1.3494201 | AT35: 9706 | AU35: =AT35/$AH35 -> 0.95400039 | AV35: 9589 | AW35: =AV35/$AH35 -> 0.94250049 | AX35: 9215
A36: 40 | B36: DO11_Dossier_Search_Lupe | C36: =E36 -> {"searchDossierOrKlient":p.DossierName2,"resultType":"Dossiers"} | E36: =F36&G36&H36&I36&J36&K36&L36&M36&N36&O36&P36&Q36&R36&S36&T36&U36&V36&W36&X36 -> {"searchDossierOrKlient":p.DossierName2,"resultType":"Dossiers"} | F36: {"searchDossierOrKlient": | G36: =G34 -> p.DossierName2 | H36: ,"resultType":" | I36: Dossiers | J36: "} | AH36: 5444 | AJ36: 5439 | AK36: =AJ36/$AH36 -> 0.99908156 | AL36: 5620 | AN36: 8913 | AP36: 7794 | AQ36: =AP36/$AH36 -> 1.4316679 | AR36: 8464 | AS36: =AR36/$AH36 -> 1.5547392 | AT36: 6464 | AU36: =AT36/$AH36 -> 1.1873622 | AV36: 10941 | AW36: =AV36/$AH36 -> 2.0097355 | AX36: 10720
A37: 41 | B37: BW03b_Bewilligungs_WF_FreigabeVerwendungsPeriode | C37: =E37 -> {"verwendungPeriode":"November 2025,Dezember 2025,Januar 2026,Februar 2026,März 2026,April 2026,Mai 2026","status":"Zu bezahlen"} | D37: yes | E37: =F37&G37&H37&I37&J37&K37&L37&M37&N37&O37&P37&Q37&R37&S37&T37&U37&V37&W37 -> {"verwendungPeriode":"November 2025,Dezember 2025,Januar 2026,Februar 2026,März 2026,April 2026,Mai 2026","status":"Zu bezahlen"} | F37: {"verwendungPeriode":" | G37: =F76&","&F77&","&F78&","&F79&","&F80&","&F81&","&F82 -> November 2025,Dezember 2025,Januar 2026,Februar 2026,März 2026,April 2026,Mai 2026 | J37: ","status":" | K37: Zu bezahlen | L37: "} | AH37: 0 | AI37: Error: locator.click: Target page, context or browser has been closedCall log:[2m - waiting for locator('tr').filter({ hasText: 'Familie' }).locator('app-enum-selection mat-select')[22m | AJ37: 5592 | AK37: =AJ37/$AH37 -> #DIV/0! | AL37: 5201 | AN37: 9343 | AP37: 10432 | AQ37: =AP37/$AH37 -> #DIV/0! | AR37: 9850 | AS37: =AR37/$AH37 -> #DIV/0! | AT37: 5044 | AU37: =AT37/$AH37 -> #DIV/0! | AV37: 6160 | AW37: =AV37/$AH37 -> #DIV/0! | AX37: 5947
B38: WSH05_Haftung_Sozialhilfeschuld_Bearbeiten | C38: =E38 -> {"haftungsType":"Einseitige Solidarhaftung erfassen","haftungDurch":`${p.FamilyName2}, ${p.ManFirstName2}`,"haftungVon":"01.01.2024","haftungBis":"31.12.2024","haftungFuer":`${p.FamilyName2}, ${p.ManFirstName3}`,"person1":"","person2":""} | E38: =F38&G38&H38&I38&J38&K38&L38&M38&N38&O38&P38&Q38&R38&S38&T38&U38&V38&W38&X38 -> {"haftungsType":"Einseitige Solidarhaftung erfassen","haftungDurch":`${p.FamilyName2}, ${p.ManFirstName2}`,"haftungVon":"01.01.2024","haftungBis":"31.12.2024","haftungFuer":`${p.FamilyName2}, ${p.ManFirstName3}`,"person1":"","person2":""} | F38: {"haftungsType":" | G38: Einseitige Solidarhaftung erfassen | H38: ","haftungDurch":` | I38: =I23 -> ${p.FamilyName2}, ${p.ManFirstName2} | J38: `,"haftungVon":" | K38: 01.01.2024 | L38: ","haftungBis":" | M38: 31.12.2024 | N38: ","haftungFuer":` | O38: ="${"&$G$5&"}, ${"&$H$47&"}" -> ${p.FamilyName2}, ${p.ManFirstName3} | P38: `,"person1":" | R38: ","person2":" | T38: "} | AK38: =AJ38/(#REF!) -> #REF! | AQ38: =AP38/(#REF!) -> #REF! | AS38: =AR38/(#REF!) -> #REF! | AU38: =AT38/(#REF!) -> #REF! | AW38: =AV38/(#REF!) -> #REF!
B39: WSH05_Haftung_Sozialhilfeschuld_Bearbeiten | C39: =E39 -> {"haftungsType":"Einzelhaftung erfassen","haftungDurch":`${p.FamilyName2}, ${p.ManFirstName2}`,"haftungVon":"01.01.2024","haftungBis":"31.12.2024","haftungFuer":`${p.FamilyName2}, ${p.GirlFirstName2}`,"person1":"","person2":""} | E39: =F39&G39&H39&I39&J39&K39&L39&M39&N39&O39&P39&Q39&R39&S39&T39&U39&V39&W39&X39 -> {"haftungsType":"Einzelhaftung erfassen","haftungDurch":`${p.FamilyName2}, ${p.ManFirstName2}`,"haftungVon":"01.01.2024","haftungBis":"31.12.2024","haftungFuer":`${p.FamilyName2}, ${p.GirlFirstName2}`,"person1":"","person2":""} | F39: {"haftungsType":" | G39: Einzelhaftung erfassen | H39: ","haftungDurch":` | I39: =I23 -> ${p.FamilyName2}, ${p.ManFirstName2} | J39: `,"haftungVon":" | K39: 01.01.2024 | L39: ","haftungBis":" | M39: 31.12.2024 | N39: ","haftungFuer":` | O39: ="${"&$G$5&"}, ${"&$H$46&"}" -> ${p.FamilyName2}, ${p.GirlFirstName2} | P39: `,"person1":" | R39: ","person2":" | T39: "} | AK39: =AJ39/(#REF!) -> #REF! | AQ39: =AP39/(#REF!) -> #REF! | AS39: =AR39/(#REF!) -> #REF! | AU39: =AT39/(#REF!) -> #REF! | AW39: =AV39/(#REF!) -> #REF!
AK40: =AJ40/(#REF!) -> #REF! | AQ40: =AP40/(#REF!) -> #REF! | AS40: =AR40/(#REF!) -> #REF! | AU40: =AT40/(#REF!) -> #REF! | AW40: =AV40/(#REF!) -> #REF!
...

Sheet 07-E2E
A1: StepNumber | B1: Action | C1: TestData | D1: Screenshot | E1: done | F1: video | G1: =5*60*1000*SpeedFaktor -> 300000 | AF1: Testresult | AG1: Run Time Step (ms) 26.06.2025 18:59:32 | AH1: Run Time Step (ms) 26.06.2025 20:17:23 | AI1: Hoch | AJ1: Run Time Step (ms) 26.06.2025 23:17:01 | AK1: Hoch
A2: 1 | B2: L00_URLAventis | C2: ='07-E2E'!B61 -> {"url":p.aventisURL} | E2: =F2&G2&H2&I2&J2&K2&L2&M2&N2&O2&P2&Q2&R2&S2&T2&U2&V2&W2&X2 -> {"url":"https://dev.aventis.swiss"} | F2: {"url":" | G2: https://dev.aventis.swiss | H2: "} | AG2: 1400 | AH2: 1127 | AI2: =AH2/$AG2 -> 0.805 | AJ2: 1450 | AK2: =AJ2/$AG2 -> 1.0357143
A3: 3 | B3: X01_Delete_BrowserCache | AG3: 0 | AH3: 1 | AI3: =AH3/$AG3 -> #DIV/0! | AJ3: 1 | AK3: =AJ3/$AG3 -> #DIV/0!
A4: 2 | B4: M01_LoginMSOnline | C4: =E4 -> {"username":"bern.sozialarbeiterin1a@diartis.ch","password":"SMze97-jkSJ59!F.","fullname":"Sozialarbeiterin 1A Bern","team":"Sozialarbeit Bern 1"} | E4: =F4&G4&H4&I4&J4&K4&L4&M4&N4&O4&P4&Q4&R4&S4&T4&U4&V4&W4&X4 -> {"username":"bern.sozialarbeiterin1a@diartis.ch","password":"SMze97-jkSJ59!F.","fullname":"Sozialarbeiterin 1A Bern","team":"Sozialarbeit Bern 1"} | F4: {"username":" | G4: bern.sozialarbeiterin1a@diartis.ch | H4: ","password":" | I4: SMze97-jkSJ59!F. | J4: ","fullname":" | K4: Sozialarbeiterin 1A Bern | L4: ","team":" | M4: Sozialarbeit Bern 1 | N4: "} | AG4: 5042 | AH4: 4441 | AI4: =AH4/$AG4 -> 0.88080127 | AJ4: 4401 | AK4: =AJ4/$AG4 -> 0.87286791
A5: 3 | B5: P01_Person_Search | C5: =E5 -> {"name":p.FamilyName7,"vorname":p.ManFirstName7,"ahvNumber":"","geburtsdatum":""} | E5: =F5&G5&H5&I5&J5&K5&L5&M5&N5&O5&P5&Q5&R5&S5&T5&U5&V5&W5&X5 -> {"name":p.FamilyName7,"vorname":p.ManFirstName7,"ahvNumber":"","geburtsdatum":""} | F5: {"name": | G5: =G57 -> p.FamilyName7 | H5: ,"vorname": | I5: =H$56 -> p.ManFirstName7 | J5: ,"ahvNumber":"" | L5: ,"geburtsdatum":" | N5: "} | Y5: B - Aufenthalterin / Aufenthalter | AG5: 1945 | AH5: 1793 | AI5: =AH5/$AG5 -> 0.9218509 | AJ5: 1684 | AK5: =AJ5/$AG5 -> 0.86580977
A6: 4 | B6: P05_Person_Create_Manual_Complete | C6: =E6 -> {"name":p.FamilyName7,"vorname":p.ManFirstName7,"ahvNumber":p.AHVNumber28,"language":"Deutsch","zivilstand":"ledig","zivilStandSeit":"28.07.2025","geburtsdatum":"20.6.1962","national":"Frankreich","gender":"männlich","aufenthalt":"","aufGultigVon":"03.10.2025","aufGueltigBis":"13.02.2026"} | E6: =F6&G6&H6&I6&J6&K6&L6&M6&N6&O6&P6&Q6&R6&S6&T6&U6&V6&W6&X6&Y6&Z6&AA6&AB6&AC6&AD6&AE6 -> {"name":p.FamilyName7,"vorname":p.ManFirstName7,"ahvNumber":p.AHVNumber28,"language":"Deutsch","zivilstand":"ledig","zivilStandSeit":"28.07.2025","geburtsdatum":"20.6.1962","national":"Frankreich","gender":"männlich","aufenthalt":"","aufGultigVon":"03.10.2025","aufGueltigBis":"13.02.2026"} | F6: {"name": | G6: =G5 -> p.FamilyName7 | H6: ,"vorname": | I6: =H$56 -> p.ManFirstName7 | J6: ,"ahvNumber": | K6: =I$59 -> p.AHVNumber28 | L6: ,"language":" | M6: Deutsch | N6: ","zivilstand":" | O6: ledig | P6: ","zivilStandSeit":" | Q6: =TEXT(TEXT(TODAY()-100,"DD")&"."&TEXT(TODAY()-100,"MM")&"."&TEXT(TODAY()-100,"YYYY"),"DD.MM.YYYY") -> 28.07.2025 | R6: ","geburtsdatum":" | S6: =TEXT(RANDBETWEEN(1,28)&"."&RANDBETWEEN(1,12)&"."&TEXT(TODAY()-23115,"YYYY"),"DD.MM.YYYY") -> 20.6.1962 | T6: ","national":" | U6: Frankreich | V6: ","gender":" | W6: männlich | X6: ","aufenthalt":" | Z6: ","aufGultigVon":" | AA6: =TEXT(TEXT(TODAY()-33,"DD")&"."&TEXT(TODAY()-33,"MM")&"."&TEXT(TODAY()-33,"YYYY"),"DD.MM.YYYY") -> 03.10.2025 | AB6: ","aufGueltigBis":" | AC6: =TEXT(TEXT(TODAY()+100,"DD")&"."&TEXT(TODAY()+100,"MM")&"."&TEXT(TODAY()+100,"YYYY"),"DD.MM.YYYY") -> 13.02.2026 | AD6: "} | AG6: 3230 | AH6: 3145 | AI6: =AH6/$AG6 -> 0.97368421 | AJ6: 3318 | AK6: =AJ6/$AG6 -> 1.0272446
A7: 5 | B7: P10_Person_Communikation_Complete | C7: =E7 -> {"mobile":"079 5641500","privateNumber":"079 5326925","email":"2213abc@gmail.com"} | E7: =F7&G7&H7&I7&J7&K7&L7&M7&N7&O7&P7&Q7&R7&S7&T7&U7&V7&W7&X7 -> {"mobile":"079 5641500","privateNumber":"079 5326925","email":"2213abc@gmail.com"} | F7: {"mobile":" | G7: ="079 "&RANDBETWEEN(5234500,5699999) -> 079 5641500 | H7: ","privateNumber":" | I7: ="079 "&RANDBETWEEN(5234500,5699999) -> 079 5326925 | J7: ","email":" | K7: =RANDBETWEEN(1111,9999)&"abc@gmail.com" -> 2213abc@gmail.com | L7: "} | AG7: 379 | AH7: 345 | AI7: =AH7/$AG7 -> 0.91029024 | AJ7: 416 | AK7: =AJ7/$AG7 -> 1.0976253
A8: 6 | B8: P15_Person_Adress | C8: =E8 -> {"zusatz":"","strasse":"Strasse_978","houseNumber":"28","ort":"3053 Münchenbuchsee","validDate":"11.7.2021"} | E8: =F8&G8&H8&I8&J8&K8&L8&M8&N8&O8&P8&Q8&R8&S8&T8&U8&V8&W8&X8 -> {"zusatz":"","strasse":"Strasse_978","houseNumber":"28","ort":"3053 Münchenbuchsee","validDate":"11.7.2021"} | F8: {"zusatz":" | H8: ","strasse":" | I8: ="Strasse_"&RANDBETWEEN(1,1000) -> Strasse_978 | J8: ","houseNumber":" | K8: =RANDBETWEEN(1,100) -> 28 | L8: ","ort":" | M8: 3053 Münchenbuchsee | N8: ","validDate":" | O8: =TEXT(RANDBETWEEN(1,28)&"."&RANDBETWEEN(1,12)&"."&TEXT(TODAY()-4*365,"YYYY"),"DD.MM.YYYY") -> 11.7.2021 | P8: "} | AG8: 4985 | AH8: 5033 | AI8: =AH8/$AG8 -> 1.0096289 | AJ8: 4853 | AK8: =AJ8/$AG8 -> 0.97352056
A9: 7 | B9: P20_Person_ZahlungsVerbindung | C9: {"iban":"CH21 0078 9100 0000 2920 0"} | AG9: 87 | AH9: 82 | AI9: =AH9/$AG9 -> 0.94252874 | AJ9: 126 | AK9: =AJ9/$AG9 -> 1.4482759
A10: 8 | B10: P30_Person_Uebernehmen | AG10: 1160 | AH10: 1165 | AI10: =AH10/$AG10 -> 1.0043103 | AJ10: 1206 | AK10: =AJ10/$AG10 -> 1.0396552
A11: 9 | B11: H01_Haushalt_Uebernehmen_Zustaendigkeit | C11: =E11 -> {"zust_Gemeinde":"Münchenbuchsee","zust_SozTeam":"Sozialarbeit Bern 1","zust_SozMitarbeiter":"Bern Sozialarbeiterin 1A","zust_SachbTeam":"Sachbearbeitung Bern","zust_SachbMitarbeiter":"Bern Sachbearbeiterin"} | E11: =F11&G11&H11&I11&J11&K11&L11&M11&N11&O11&P11&Q11&R11&S11&T11&U11&V11&W11&X11 -> {"zust_Gemeinde":"Münchenbuchsee","zust_SozTeam":"Sozialarbeit Bern 1","zust_SozMitarbeiter":"Bern Sozialarbeiterin 1A","zust_SachbTeam":"Sachbearbeitung Bern","zust_SachbMitarbeiter":"Bern Sachbearbeiterin"} | F11: {"zust_Gemeinde":" | G11: Münchenbuchsee | H11: ","zust_SozTeam":" | I11: Sozialarbeit Bern 1 | J11: ","zust_SozMitarbeiter":" | K11: Bern Sozialarbeiterin 1A | L11: ","zust_SachbTeam":" | M11: Sachbearbeitung Bern | N11: ","zust_SachbMitarbeiter":" | O11: Bern Sachbearbeiterin | P11: "} | AG11: 3992 | AH11: 4057 | AI11: =AH11/$AG11 -> 1.0162826 | AJ11: 4001 | AK11: =AJ11/$AG11 -> 1.0022545
A12: 10 | B12: D01_Dossier_Eroeffnen | C12: =E12 -> {"dossierBezeichnung":p.DossierName7,"eroeffnetAm":"05.11.2025","dossierSprache":"Deutsch"} | E12: =F12&G12&H12&I12&J12&K12&L12&M12&N12&O12&P12&Q12&R12&S12&T12&U12&V12&W12&X12 -> {"dossierBezeichnung":p.DossierName7,"eroeffnetAm":"05.11.2025","dossierSprache":"Deutsch"} | F12: {"dossierBezeichnung": | G12: =G56 -> p.DossierName7 | H12: ,"eroeffnetAm":" | I12: =TEXT(TEXT(TODAY(),"DD")&"."&TEXT(TODAY(),"MM")&"."&TEXT(TODAY(),"YYYY"),"DD.MM.YYYY") -> 05.11.2025 | J12: ","dossierSprache":" | K12: Deutsch | L12: "} | AG12: 1059 | AH12: 1028 | AI12: =AH12/$AG12 -> 0.9707271 | AJ12: 908 | AK12: =AJ12/$AG12 -> 0.85741265
A13: 13 | B13: BW04_ZahlungsVerbindung_Freigeben | C13: =E13 -> {"dossierInstitution":p.DossierName7,"klientschaft":`${p.FamilyName7}, ${p.ManFirstName7}`,"buttonBewilligung":"Anfragen","checkStatus":"In Bearbeitung"} | E13: =F13&G13&H13&I13&J13&K13&L13&M13&N13&O13&P13&Q13&R13&S13&T13&U13&V13&W13&X13 -> {"dossierInstitution":p.DossierName7,"klientschaft":`${p.FamilyName7}, ${p.ManFirstName7}`,"buttonBewilligung":"Anfragen","checkStatus":"In Bearbeitung"} | F13: {"dossierInstitution": | G13: =G12 -> p.DossierName7 | H13: ,"klientschaft":` | I13: =I23 -> ${p.FamilyName7}, ${p.ManFirstName7} | J13: `,"buttonBewilligung":" | K13: Anfragen | L13: ","checkStatus":" | M13: In Bearbeitung | N13: "} | AG13: 10602 | AH13: 12109 | AI13: =AH13/$AG13 -> 1.142143 | AJ13: 10673 | AK13: =AJ13/$AG13 -> 1.0066968
A14: 14 | B14: L03_LogoutAndLoginDiffAccount | C14: =E14 -> {"username":"Bern.Sachbearbeiterin@diartis.ch","password":"XXxa22?pdTA66-S@"} | E14: =F14&G14&H14&I14&J14&K14&L14&M14&N14&O14&P14&Q14&R14&S14&T14&U14&V14&W14&X14 -> {"username":"Bern.Sachbearbeiterin@diartis.ch","password":"XXxa22?pdTA66-S@"} | F14: {"username":" | G14: Bern.Sachbearbeiterin@diartis.ch | H14: ","password":" | I14: XXxa22?pdTA66-S@ | J14: "} | AG14: 9576 | AH14: 8975 | AI14: =AH14/$AG14 -> 0.93723893 | AJ14: 9108 | AK14: =AJ14/$AG14 -> 0.95112782
A15: 15 | B15: BW04_ZahlungsVerbindung_Freigeben | C15: =E15 -> {"dossierInstitution":p.DossierName1,"klientschaft":`${p.FamilyName7}, ${p.ManFirstName7}`,"buttonBewilligung":"Bewilligen","checkStatus":"Bewilligt"} | E15: =F15&G15&H15&I15&J15&K15&L15&M15&N15&O15&P15&Q15&R15&S15&T15&U15&V15&W15&X15 -> {"dossierInstitution":p.DossierName1,"klientschaft":`${p.FamilyName7}, ${p.ManFirstName7}`,"buttonBewilligung":"Bewilligen","checkStatus":"Bewilligt"} | F15: {"dossierInstitution": | G15: p.DossierName1 | H15: ,"klientschaft":` | I15: =I23 -> ${p.FamilyName7}, ${p.ManFirstName7} | J15: `,"buttonBewilligung":" | K15: Bewilligen | L15: ","checkStatus":" | M15: Bewilligt | N15: "} | AG15: 9599 | AH15: 9790 | AI15: =AH15/$AG15 -> 1.0198979 | AJ15: 10044 | AK15: =AJ15/$AG15 -> 1.046359
A16: 16 | B16: L03_LogoutAndLoginDiffAccount | C16: {"username":"bern.sozialarbeiterin1a@diartis.ch","password":"SMze97-jkSJ59!F."} | E16: 2 | F16: {"username":" | G16: Bern.Sachbearbeiterin@diartis.ch | H16: ","password":" | I16: XXxa22?pdTA66-S@ | J16: "} | AG16: 8927 | AH16: 8847 | AI16: =AH16/$AG16 -> 0.99103842 | AJ16: 9747 | AK16: =AJ16/$AG16 -> 1.0918562
A17: 18 | B17: DO11_Dossier_Search_Lupe | C17: =E17 -> {"searchDossierOrKlient":p.DossierName1,"resultType":"Dossiers"} | E17: =F17&G17&H17&I17&J17&K17&L17&M17&N17&O17&P17&Q17&R17&S17&T17&U17&V17&W17&X17 -> {"searchDossierOrKlient":p.DossierName1,"resultType":"Dossiers"} | F17: {"searchDossierOrKlient": | G17: p.DossierName1 | H17: ,"resultType":" | I17: Dossiers | J17: "} | AG17: 5773 | AH17: 5789 | AI17: =AH17/$AG17 -> 1.0027715 | AJ17: 5769 | AK17: =AJ17/$AG17 -> 0.99930712
A18: 20 | B18: WO32_01b_Wohnsituation_Haushalt_Wohnung_anpassen | C18: =E18 -> {"vermieter":"Graber Immobilien","wohnungsgrosse":"4 Zimmer","mietkosten":1200,"nebenkosten":100} | E18: =F18&G18&H18&I18&J18&K18&L18&M18&N18&O18&P18&Q18&R18&S18&T18&U18&V18&W18&X18 -> {"vermieter":"Graber Immobilien","wohnungsgrosse":"4 Zimmer","mietkosten":1200,"nebenkosten":100} | F18: {"vermieter":" | G18: Graber Immobilien | H18: ","wohnungsgrosse":" | I18: 4 Zimmer | J18: ","mietkosten": | K18: 1200 | L18: ,"nebenkosten": | M18: 100 | N18: } | AG18: 3502 | AH18: 3410 | AI18: =AH18/$AG18 -> 0.9737293 | AJ18: 3637 | AK18: =AJ18/$AG18 -> 1.0385494
A19: 22 | B19: WO30_Wohnsituation_Haushalt_Person_Hinzufuegen | C19: =E19 -> {"name":p.FamilyName7,"vorname":p.ManFirstName8,"geburtsdatum":p.BirthdayAdult7,"ahvNumber":p.AHVNumber25,"personInhausltVon":"28.07.2025","inHauslt":"Übernehmen","ereignis":"Eheschliessung"} | E19: =F19&G19&H19&I19&J19&K19&L19&M19&N19&O19&P19&Q19&R19&S19&T19&U19&V19&W19&X19 -> {"name":p.FamilyName7,"vorname":p.ManFirstName8,"geburtsdatum":p.BirthdayAdult7,"ahvNumber":p.AHVNumber25,"personInhausltVon":"28.07.2025","inHauslt":"Übernehmen","ereignis":"Eheschliessung"} | F19: {"name": | G19: =G6 -> p.FamilyName7 | H19: ,"vorname": | I19: =H59 -> p.ManFirstName8 | J19: ,"geburtsdatum": | K19: =J60 -> p.BirthdayAdult7 | L19: ,"ahvNumber": | M19: =I60 -> p.AHVNumber25 | N19: ,"personInhausltVon":" | O19: =TEXT(TEXT(TODAY()-100,"DD")&"."&TEXT(TODAY()-100,"MM")&"."&TEXT(TODAY()-100,"YYYY"),"DD.MM.YYYY") -> 28.07.2025 | P19: ","inHauslt":" | Q19: Übernehmen | R19: ","ereignis":" | S19: Eheschliessung | T19: "} | AG19: 2413 | AH19: 2207 | AI19: =AH19/$AG19 -> 0.91462909 | AJ19: 2250 | AK19: =AJ19/$AG19 -> 0.93244923
A20: 23 | B20: WO30_Wohnsituation_Haushalt_Person_Hinzufuegen | C20: =E20 -> {"name":p.FamilyName7,"vorname":p.WomanFirstName7,"geburtsdatum":p.BirthdayAdult8,"ahvNumber":p.AHVNumber26,"personInhausltVon":"28.07.2025","inHauslt":"Übernehmen","ereignis":"Geburt"} | E20: =F20&G20&H20&I20&J20&K20&L20&M20&N20&O20&P20&Q20&R20&S20&T20&U20&V20&W20&X20 -> {"name":p.FamilyName7,"vorname":p.WomanFirstName7,"geburtsdatum":p.BirthdayAdult8,"ahvNumber":p.AHVNumber26,"personInhausltVon":"28.07.2025","inHauslt":"Übernehmen","ereignis":"Geburt"} | F20: {"name": | G20: =G19 -> p.FamilyName7 | H20: ,"vorname": | I20: =H61 -> p.WomanFirstName7 | J20: ,"geburtsdatum": | K20: =J61 -> p.BirthdayAdult8 | L20: ,"ahvNumber": | M20: =I61 -> p.AHVNumber26 | N20: ,"personInhausltVon":" | O20: =TEXT(TEXT(TODAY()-100,"DD")&"."&TEXT(TODAY()-100,"MM")&"."&TEXT(TODAY()-100,"YYYY"),"DD.MM.YYYY") -> 28.07.2025 | P20: ","inHauslt":" | Q20: Übernehmen | R20: ","ereignis":" | S20: Geburt | T20: "} | AG20: 3208 | AH20: 2743 | AI20: =AH20/$AG20 -> 0.85504988 | AJ20: 3298 | AK20: =AJ20/$AG20 -> 1.0280549
A21: 24 | B21: WO30_Wohnsituation_Haushalt_Person_Hinzufuegen | C21: =E21 -> {"name":p.FamilyName7,"vorname":p.GirlFirstName7,"geburtsdatum":p.BirthdayKid7,"ahvNumber":p.AHVNumber27,"personInhausltVon":"28.07.2025","inHauslt":"Übernehmen","ereignis":"Geburt"} | E21: =F21&G21&H21&I21&J21&K21&L21&M21&N21&O21&P21&Q21&R21&S21&T21&U21&V21&W21&X21 -> {"name":p.FamilyName7,"vorname":p.GirlFirstName7,"geburtsdatum":p.BirthdayKid7,"ahvNumber":p.AHVNumber27,"personInhausltVon":"28.07.2025","inHauslt":"Übernehmen","ereignis":"Geburt"} | F21: {"name": | G21: =G20 -> p.FamilyName7 | H21: ,"vorname": | I21: =H62 -> p.GirlFirstName7 | J21: ,"geburtsdatum": | K21: =J62 -> p.BirthdayKid7 | L21: ,"ahvNumber": | M21: =I62 -> p.AHVNumber27 | N21: ,"personInhausltVon":" | O21: =TEXT(TEXT(TODAY()-100,"DD")&"."&TEXT(TODAY()-100,"MM")&"."&TEXT(TODAY()-100,"YYYY"),"DD.MM.YYYY") -> 28.07.2025 | P21: ","inHauslt":" | Q21: Übernehmen | R21: ","ereignis":" | S21: Geburt | T21: "} | AG21: 2738 | AH21: 2759 | AI21: =AH21/$AG21 -> 1.0076698 | AJ21: 2595 | AK21: =AJ21/$AG21 -> 0.9477721
A22: 25 | B22: WO32_01b_Wohnsituation_Haushalt_Wohnung_anpassen | C22: =E22 -> {"vermieter":"Graber Immobilien","wohnungsgrosse":"4 Zimmer","mietkosten":3000,"nebenkosten":300} | E22: =F22&G22&H22&I22&J22&K22&L22&M22&N22&O22&P22&Q22&R22&S22&T22&U22&V22&W22&X22 -> {"vermieter":"Graber Immobilien","wohnungsgrosse":"4 Zimmer","mietkosten":3000,"nebenkosten":300} | F22: {"vermieter":" | G22: Graber Immobilien | H22: ","wohnungsgrosse":" | I22: 4 Zimmer | J22: ","mietkosten": | K22: 3000 | L22: ,"nebenkosten": | M22: 300 | N22: } | AG22: 2971 | AH22: 3474 | AI22: =AH22/$AG22 -> 1.1693033 | AJ22: 3138 | AK22: =AJ22/$AG22 -> 1.05621
A23: 26 | B23: KL01_Klientschaft_select | C23: =E23 -> {"dossier":p.DossierName7,"klientschaft":`${p.FamilyName7}, ${p.ManFirstName7}`} | E23: =F23&G23&H23&I23&J23&K23&L23&M23&N23&O23&P23&Q23&R23&S23&T23&U23&V23&W23&X23 -> {"dossier":p.DossierName7,"klientschaft":`${p.FamilyName7}, ${p.ManFirstName7}`} | F23: {"dossier": | G23: =G12 -> p.DossierName7 | H23: ,"klientschaft":` | I23: ="${"&$G$5&"}, ${"&$I$5&"}" -> ${p.FamilyName7}, ${p.ManFirstName7} | J23: `} | AG23: 4894 | AH23: 4833 | AI23: =AH23/$AG23 -> 0.98753576 | AJ23: 4899 | AK23: =AJ23/$AG23 -> 1.0010217
A24: 27 | B24: KL03_ErwerbsituationEinnahmen_Lohn_erfassen | C24: =E24 -> {"panelTitle":"Erwerbssituation / Einnahmen","zahlbarDurch":"BKW Energie AG","pensumm":"100","betrag":"1000","gueltigVon":"01.01.2024","gueltigBis":"31.12.2025","checkbox":"x"} | E24: =F24&G24&H24&I24&J24&K24&L24&M24&N24&O24&P24&Q24&R24&S24&T24&U24&V24&W24&X24 -> {"panelTitle":"Erwerbssituation / Einnahmen","zahlbarDurch":"BKW Energie AG","pensumm":"100","betrag":"1000","gueltigVon":"01.01.2024","gueltigBis":"31.12.2025","checkbox":"x"} | F24: {"panelTitle":" | G24: Erwerbssituation / Einnahmen | H24: ","zahlbarDurch":" | I24: BKW Energie AG | J24: ","pensumm":" | K24: 100 | L24: ","betrag":" | M24: 1000 | N24: ","gueltigVon":" | O24: ="01.01."&YEAR((TODAY()-366)) -> 01.01.2024 | P24: ","gueltigBis":" | Q24: ="31.12."&YEAR(TODAY()) -> 31.12.2025 | R24: ","checkbox":" | S24: x | T24: "} | AG24: 3432 | AH24: 3242 | AI24: =AH24/$AG24 -> 0.94463869 | AJ24: 3433 | AK24: =AJ24/$AG24 -> 1.0002914
B25: KL0X_ErwerbsituationEinnahmen_erfassen | C25: =E25 -> {"dossier":p.DossierName7,"klientschaft":`${p.FamilyName7}, ${p.ManFirstName7}`,"topMenu":"Erwerbseinkommen","subMenu":"Unselbständiges Erwerbseinkommen","zahlbarDurch":"Berner Schuldenberatung","pensumm":"30","13Ja":"x","betrag":"1500","gueltigVon":"0","gueltigBis":"31.12.2025","schweregrad":""} | E25: =F25&G25&H25&I25&J25&K25&L25&M25&N25&O25&P25&Q25&R25&S25&T25&U25&V25&W25&X25&Y25&Z25&AA25&AB25&AC25 -> {"dossier":p.DossierName7,"klientschaft":`${p.FamilyName7}, ${p.ManFirstName7}`,"topMenu":"Erwerbseinkommen","subMenu":"Unselbständiges Erwerbseinkommen","zahlbarDurch":"Berner Schuldenberatung","pensumm":"30","13Ja":"x","betrag":"1500","gueltigVon":"0","gueltigBis":"31.12.2025","schweregrad":""} | F25: {"dossier": | G25: =G23 -> p.DossierName7 | H25: ,"klientschaft":` | I25: =I23 -> ${p.FamilyName7}, ${p.ManFirstName7} | J25: `,"topMenu":" | K25: Erwerbseinkommen | L25: ","subMenu":" | M25: Unselbständiges Erwerbseinkommen | N25: ","zahlbarDurch":" | O25: Berner Schuldenberatung | P25: ","pensumm":" | Q25: 30 | R25: ","13Ja":" | S25: x | T25: ","betrag":" | U25: 1500 | V25: ","gueltigVon":" | W25: =W24 -> 0 | X25: ","gueltigBis":" | Y25: ="31.12."&YEAR(TODAY()) -> 31.12.2025 | Z25: ","schweregrad":" | AB25: "} | AI25: =AH25/$AG25 -> #DIV/0! | AK25: =AJ25/$AG25 -> #DIV/0!
A26: 28 | B26: DO11_Dossier_Search_Lupe | C26: =E26 -> {"searchDossierOrKlient":p.DossierName1,"resultType":"Dossiers"} | E26: =F26&G26&H26&I26&J26&K26&L26&M26&N26&O26&P26&Q26&R26&S26&T26&U26&V26&W26&X26 -> {"searchDossierOrKlient":p.DossierName1,"resultType":"Dossiers"} | F26: {"searchDossierOrKlient": | G26: p.DossierName1 | H26: ,"resultType":" | I26: Dossiers | J26: "} | AG26: 4993 | AH26: 4923 | AI26: =AH26/$AG26 -> 0.98598037 | AJ26: 4861 | AK26: =AJ26/$AG26 -> 0.97356299
A27: 30 | B27: A01_AnspruchPruefung_Bedarfspruefung | C27: =E27 -> {"entscheidVom":"05.11.2025","begrundung":"Gar keine Begründung","unterstutzungab":"01.11.2025"} | E27: =F27&G27&H27&I27&J27&K27&L27&M27&N27&O27&P27&Q27&R27&S27&T27&U27&V27&W27&X27 -> {"entscheidVom":"05.11.2025","begrundung":"Gar keine Begründung","unterstutzungab":"01.11.2025"} | F27: {"entscheidVom":" | G27: =TEXT(TEXT(TODAY(),"DD")&"."&TEXT(TODAY(),"MM")&"."&TEXT(TODAY(),"YYYY"),"DD.MM.YYYY") -> 05.11.2025 | H27: ","begrundung":" | I27: Gar keine Begründung | J27: ","unterstutzungab":" | K27: =TEXT(TEXT(1,"DD")&"."&TEXT(TODAY(),"MM")&"."&TEXT(TODAY(),"YYYY"),"DD.MM.YYYY") -> 01.11.2025 | L27: "} | AG27: 10626 | AH27: 10634 | AI27: =AH27/$AG27 -> 1.0007529 | AJ27: 10692 | AK27: =AJ27/$AG27 -> 1.0062112
A28: 32 | B28: R01_Rahmenbudget_Wohnkosten_Anpassen_V2 | C28: =E28 -> {"ubernahmeWohnkostenCFH":"100","uebernahmeWohnkostenVon":"01.11.2025","uebernahmeWohnkostenBis":"27.5.2026","uebernahemBegruendung":"Die Wohnungen sind teuer hier"} | E28: =F28&G28&H28&I28&J28&K28&L28&M28&N28&O28&P28&Q28&R28&S28&T28&U28&V28&W28&X28 -> {"ubernahmeWohnkostenCFH":"100","uebernahmeWohnkostenVon":"01.11.2025","uebernahmeWohnkostenBis":"27.5.2026","uebernahemBegruendung":"Die Wohnungen sind teuer hier"} | F28: {"ubernahmeWohnkostenCFH":" | G28: 100 | H28: ","uebernahmeWohnkostenVon":" | I28: ="01."&MONTH(TODAY())&"."&YEAR(TODAY()) -> 01.11.2025 | J28: ","uebernahmeWohnkostenBis":" | K28: ="27."&MONTH(TODAY()+180)&"."&YEAR(TODAY()+180) -> 27.5.2026 | L28: ","uebernahemBegruendung":" | M28: Die Wohnungen sind teuer hier | N28: "} | AG28: 1630 | AH28: 1369 | AJ28: 1982
B29: BW01_Bewilligungs_Workflow_LeistungsEntscheid | C29: =E29 -> {"lEvonDate":"05.11.2025","lEbisDate":"05.11.2026","checkStatus":"In Bearbeitung"} | E29: =F29&G29&H29&I29&J29&K29&L29&M29&N29&O29&P29&Q29&R29&S29&T29&U29&V29&W29&X29 -> {"lEvonDate":"05.11.2025","lEbisDate":"05.11.2026","checkStatus":"In Bearbeitung"} | F29: {"lEvonDate":" | G29: =TEXT(TEXT(TODAY(),"DD")&"."&TEXT(TODAY(),"MM")&"."&TEXT(TODAY(),"YYYY"),"DD.MM.YYYY") -> 05.11.2025 | H29: ","lEbisDate":" | I29: =TEXT(TEXT(TODAY(),"DD")&"."&TEXT(TODAY()+366,"MM")&"."&TEXT(TODAY()+366,"YYYY"),"DD.MM.YYYY") -> 05.11.2026 | J29: ","checkStatus":" | K29: In Bearbeitung | L29: "} | AI29: =AH29/(#REF!) -> #REF! | AK29: =AJ29/(#REF!) -> #REF!
B30: E01_Delay | C30: {"Pause":"1000"} | AI30: =AH30/(#REF!) -> #REF! | AK30: =AJ30/(#REF!) -> #REF!
